<?xml version="1.0" encoding="utf-8"?>
<!-- =================================================================================== -->
<!-- |    This document was autogenerated by xacro from tom_full.urdf.xacro            | -->
<!-- |    EDITING THIS FILE BY HAND IS NOT RECOMMENDED                                 | -->
<!-- =================================================================================== -->
<!--

	Author: Emmanuel Dean dean@tum.de
  
  This work is licensed under the Creative Commons Attribution-NonCommercial-NoDerivs 3.0 Unported License.
  To view a copy of this license, visit http://creativecommons.org/licenses/by-nc-nd/3.0/ or send a letter to
  Creative Commons, 444 Castro Street, Suite 900, Mountain View, California, 94041, USA.
-->
<robot name="tomm" xmlns:controller="http://playerstage.sourceforge.net/gazebo/xmlschema/#controller" xmlns:interface="http://playerstage.sourceforge.net/gazebo/xmlschema/#interface" xmlns:sensor="http://playerstage.sourceforge.net/gazebo/xmlschema/#sensor">
  <material name="Blue">
    <color rgba="0.0 0.0 0.8 1.0"/>
  </material>
  <material name="Green">
    <color rgba="0.0 0.8 0.0 1.0"/>
  </material>
  <material name="Grey">
    <color rgba="0.7 0.7 0.7 1.0"/>
  </material>
  <material name="LightGrey">
    <color rgba="0.9 0.9 0.9 1.0"/>
  </material>
  <material name="DarkGrey">
    <color rgba="0.2 0.2 0.2 1.0"/>
  </material>
  <material name="Red">
    <color rgba="0.8 0.0 0.0 1.0"/>
  </material>
  <material name="White">
    <color rgba="1.0 1.0 1.0 1.0"/>
  </material>
  <gazebo>
    <plugin filename="libgazebo_ros_control.so" name="ros_control">
      <robotNamespace>/tomm</robotNamespace>
      <controlPeriod>0.001</controlPeriod>
      <!--robotSimType>gazebo_ros_control/DefaultRobotHWSim</robotSimType-->
      <robotSimType>tomm_hardware_gazebo/TOMMHardwareGazebo</robotSimType>
    </plugin>
  </gazebo>
  <!-- measured from model -->
  <!--xacro:property name="shoulder_height" value="0.089159" /-->
  <!--xacro:property name="shoulder_offset" value="0.13585" /-->
  <!-- shoulder_offset - elbow_offset + wrist_1_length = 0.10915 -->
  <!--xacro:property name="upper_arm_length" value="0.42500" /-->
  <!--xacro:property name="elbow_offset" value="0.1197" /-->
  <!-- CAD measured -->
  <!--xacro:property name="forearm_length" value="0.39225" /-->
  <!--xacro:property name="wrist_1_length" value="0.093" /-->
  <!-- CAD measured -->
  <!--xacro:property name="wrist_2_length" value="0.09465" /-->
  <!-- In CAD this distance is 0.930, but in the spec it is 0.09465 -->
  <!--xacro:property name="wrist_3_length" value="0.0823" /-->
  <!-- manually measured -->
  <!-- ======================== BASE PARAMS ========================= -->
  <!-- ======================== FINGER PARAMS ======================== -->
  <!--0.002298-->
  <!-- ========================= THUMB PARAMS ========================= -->
  <!-- ========================= LIMITS ========================= -->
  <!-- ============================================================================= -->
  <!-- ============================================================================= -->
  <!-- ============================================================================= -->
  <!-- END THUMB MACRO -->
  <!-- [[END]] THREE FINGER MACRO -->
  <!-- ======================== BASE PARAMS ========================= -->
  <!-- ======================== FINGER PARAMS ======================== -->
  <!--0.002298-->
  <!-- ========================= THUMB PARAMS ========================= -->
  <!-- ========================= LIMITS ========================= -->
  <!-- ============================================================================= -->
  <!-- ============================================================================= -->
  <!-- ============================================================================= -->
  <!-- END THUMB MACRO -->
  <!-- [[END]] THREE FINGER MACRO -->
  <!-- Mobile base block  -->
  <link name="base_link">
    <visual>
      <origin rpy="1.5707963259 0 1.5707963259" xyz="0.4 0 0.5"/>
      <geometry>
        <mesh filename="package://tomm_description/meshes/base/item_profile.dae"/>
      </geometry>
      <material name="LightGrey"/>
    </visual>
    <collision>
      <geometry>
        <mesh filename="package://tomm_description/meshes/base/item_profile_collision.dae" scale="0.001 0.0009 0.001"/>
      </geometry>
      <origin rpy="1.5707963259 0 -1.5707963259" xyz="0.55 0.35 0.03"/>
    </collision>
    <inertial>
      <origin xyz="-0.05 0 0.0"/>
      <mass value="250.0"/>
      <inertia ixx="34.82" ixy="0.001" ixz="0.001" iyy="38.20" iyz="0.001" izz="23.54"/>
    </inertial>
  </link>
  <!-- Torso link -->
  <link name="torso_link">
    <visual>
      <origin rpy="1.57 0 1.57" xyz="-0.01614 0 -0.76268"/>
      <geometry>
        <mesh filename="package://tomm_description/meshes/base/green_parts.dae"/>
      </geometry>
      <material name="Green"/>
    </visual>
    <collision>
      <geometry>
        <mesh filename="package://tomm_description/meshes/base/green_parts_collision.dae"/>
      </geometry>
      <origin rpy="1.5707963259 0 1.5707963259" xyz="-0.11 -0.16 -0.8"/>
    </collision>
    <inertial>
      <origin xyz="0 0 0.44"/>
      <mass value="25"/>
      <inertia ixx="8.9" ixy="0.017" ixz="0.01" iyy="6.37" iyz="2.2" izz="6.33"/>
    </inertial>
  </link>
  <joint name="base_to_torso" type="fixed">
    <parent link="base_link"/>
    <child link="torso_link"/>
    <origin xyz="0.41614 0 1.26268"/>
  </joint>
  <!-- Wheels-->
  <link name="l_front_wheel_link">
    <visual>
      <geometry>
        <mesh filename="package://tomm_description/meshes/wheels/wheels.dae"/>
      </geometry>
      <material name="white">
        <color rgba="1 1 1 1"/>
      </material>
    </visual>
    <collision>
      <origin rpy="0 0 0" xyz="0 0 0"/>
      <geometry>
        <cylinder length="0.075" radius="0.1"/>
      </geometry>
    </collision>
    <inertial>
      <mass value="2.0"/>
      <inertia ixx="0.0059375" ixy="0.0" ixz="0.0" iyy="0.0059375" iyz="0.0" izz="0.01"/>
    </inertial>
  </link>
  <gazebo reference="l_front_wheel_link">
    <material>Gazebo/Grey</material>
  </gazebo>
  <!-- continuous not working! -->
  <joint name="l_front_wheel_joint" type="fixed">
    <parent link="base_link"/>
    <child link="l_front_wheel_link"/>
    <dynamics damping="0" friction="0"/>
    <origin rpy="-1.57 0 0" xyz="0.4 0.303 0.1"/>
    <axis xyz="0 0 1"/>
  </joint>
  <!--xacro:wheels_transmission prefix="${prefix}"/-->
  <link name="l_rear_wheel_link">
    <visual>
      <geometry>
        <mesh filename="package://tomm_description/meshes/wheels/wheels.dae"/>
      </geometry>
      <material name="white">
        <color rgba="1 1 1 1"/>
      </material>
    </visual>
    <collision>
      <origin rpy="0 0 0" xyz="0 0 0"/>
      <geometry>
        <cylinder length="0.075" radius="0.1"/>
      </geometry>
    </collision>
    <inertial>
      <mass value="2.0"/>
      <inertia ixx="0.0059375" ixy="0.0" ixz="0.0" iyy="0.0059375" iyz="0.0" izz="0.01"/>
    </inertial>
  </link>
  <gazebo reference="l_rear_wheel_link">
    <material>Gazebo/Grey</material>
  </gazebo>
  <!-- continuous not working! -->
  <joint name="l_rear_wheel_joint" type="fixed">
    <parent link="base_link"/>
    <child link="l_rear_wheel_link"/>
    <dynamics damping="0" friction="0"/>
    <origin rpy="-1.57 0 0" xyz="-0.4115 0.303 0.1"/>
    <axis xyz="0 0 1"/>
  </joint>
  <!--xacro:wheels_transmission prefix="${prefix}"/-->
  <link name="r_front_wheel_link">
    <visual>
      <geometry>
        <mesh filename="package://tomm_description/meshes/wheels/wheels.dae"/>
      </geometry>
      <material name="white">
        <color rgba="1 1 1 1"/>
      </material>
    </visual>
    <collision>
      <origin rpy="0 0 0" xyz="0 0 0"/>
      <geometry>
        <cylinder length="0.075" radius="0.1"/>
      </geometry>
    </collision>
    <inertial>
      <mass value="2.0"/>
      <inertia ixx="0.0059375" ixy="0.0" ixz="0.0" iyy="0.0059375" iyz="0.0" izz="0.01"/>
    </inertial>
  </link>
  <gazebo reference="r_front_wheel_link">
    <material>Gazebo/Grey</material>
  </gazebo>
  <!-- continuous not working! -->
  <joint name="r_front_wheel_joint" type="fixed">
    <parent link="base_link"/>
    <child link="r_front_wheel_link"/>
    <dynamics damping="0" friction="0"/>
    <origin rpy="-1.57 0 0" xyz="0.4 -0.303 0.1"/>
    <axis xyz="0 0 1"/>
  </joint>
  <!--xacro:wheels_transmission prefix="${prefix}"/-->
  <link name="r_rear_wheel_link">
    <visual>
      <geometry>
        <mesh filename="package://tomm_description/meshes/wheels/wheels.dae"/>
      </geometry>
      <material name="white">
        <color rgba="1 1 1 1"/>
      </material>
    </visual>
    <collision>
      <origin rpy="0 0 0" xyz="0 0 0"/>
      <geometry>
        <cylinder length="0.075" radius="0.1"/>
      </geometry>
    </collision>
    <inertial>
      <mass value="2.0"/>
      <inertia ixx="0.0059375" ixy="0.0" ixz="0.0" iyy="0.0059375" iyz="0.0" izz="0.01"/>
    </inertial>
  </link>
  <gazebo reference="r_rear_wheel_link">
    <material>Gazebo/Grey</material>
  </gazebo>
  <!-- continuous not working! -->
  <joint name="r_rear_wheel_joint" type="fixed">
    <parent link="base_link"/>
    <child link="r_rear_wheel_link"/>
    <dynamics damping="0" friction="0"/>
    <origin rpy="-1.57 0 0" xyz="-0.4115 -0.303 0.1"/>
    <axis xyz="0 0 1"/>
  </joint>
  <!--xacro:wheels_transmission prefix="${prefix}"/-->
  <!-- Deco Logos-->
  <link name="ICS_logo_blue_link">
    <visual>
      <origin rpy="1.57 0 1.57" xyz="0 0 0"/>
      <geometry>
        <mesh filename="package://tomm_description/meshes/base/logo_blue.dae"/>
      </geometry>
    </visual>
    <collision>
      <origin rpy="1.57 0 1.57" xyz="0 0 0"/>
      <geometry>
        <mesh filename="package://tomm_description/meshes/base/logo_blue.dae"/>
      </geometry>
    </collision>
  </link>
  <joint name="ICS_logo_blue" type="fixed">
    <parent link="base_link"/>
    <child link="ICS_logo_blue_link"/>
    <origin xyz="0.4 0 0.5"/>
  </joint>
  <link name="ICS_logo_grey_link">
    <visual>
      <origin rpy="1.57 0 1.57" xyz="0 0 0"/>
      <geometry>
        <mesh filename="package://tomm_description/meshes/base/logo_grey.dae"/>
      </geometry>
    </visual>
    <collision>
      <origin rpy="1.57 0 1.57" xyz="0 0 0"/>
      <geometry>
        <mesh filename="package://tomm_description/meshes/base/logo_grey.dae"/>
      </geometry>
    </collision>
  </link>
  <joint name="ICS_logo_grey" type="fixed">
    <parent link="base_link"/>
    <child link="ICS_logo_grey_link"/>
    <origin xyz="0.4 0 0.5"/>
  </joint>
  <gazebo reference="base_link">
    <material>Gazebo/White</material>
    <selfCollide>false</selfCollide>
  </gazebo>
  <gazebo reference="torso_link">
    <material>Gazebo/Green</material>
    <selfCollide>false</selfCollide>
  </gazebo>
  <gazebo reference="ICS_logo_blue_link">
    <material>Gazebo/Blue</material>
    <selfCollide>false</selfCollide>
  </gazebo>
  <gazebo reference="ICS_logo_grey_link">
    <material>Gazebo/Grey</material>
    <selfCollide>false</selfCollide>
  </gazebo>
  <!-- Add this line to add self collisions in the simulator (Must be inside <gazebo tag>) -->
  <!--    <selfCollide>true</selfCollide>     -->
  <!-- robot head, includes the left camera -->
  <link name="tom_left_camera_link">
    <visual>
      <origin rpy="0 0 0" xyz="0 0 0"/>
      <geometry>
        <box size="0.01 0.01 0.01"/>
      </geometry>
      <material name="orange">
        <color rgba="0.45 0.45 0.45 1.0"/>
      </material>
    </visual>
  </link>
  <link name="tom_head_link">
    <visual>
      <origin rpy="1.57079632679 0 -1.57079632679" xyz="1 1.255 -0.838"/>
      <geometry>
        <mesh filename="package://tomm_description/meshes/head/head.stl" scale="0.001 0.001 0.001"/>
      </geometry>
      <material name="green">
        <color rgba="0.0 0.8 0.0 1"/>
      </material>
    </visual>
  </link>
  <joint name="table_head_joint" type="fixed">
    <origin rpy="0 0 0" xyz="0 0 0"/>
    <parent link="torso_link"/>
    <child link="tom_head_link"/>
  </joint>
  <joint name="tom_left_camera_joint" type="fixed">
    <origin rpy="-2.43606 -0.193804 -1.648299" xyz="0.075241 0.032279 0.211305"/>
    <parent link="torso_link"/>
    <child link="tom_left_camera_link"/>
  </joint>
  <link name="l_base_link">
    <visual>
      <geometry>
        <mesh filename="package://tomm_description/meshes/arm/ur5/visual/Base.dae"/>
      </geometry>
      <material name="LightGrey">
        <color rgba="0.7 0.7 0.7 1.0"/>
      </material>
    </visual>
    <collision>
      <geometry>
        <!--mesh filename="package://tomm_description/meshes/arm/ur5/collision/base.stl" /-->
        <cylinder length="0.05" radius="0.08"/>
      </geometry>
    </collision>
    <inertial>
      <mass value="4.0"/>
      <origin rpy="0 0 0" xyz="0.0 0.0 0.0"/>
      <inertia ixx="0.00443333156" ixy="0.0" ixz="0.0" iyy="0.00443333156" iyz="0.0" izz="0.0072"/>
    </inertial>
  </link>
  <joint name="l_shoulder_pan_joint" type="revolute">
    <parent link="l_base_link"/>
    <child link="l_shoulder_link"/>
    <origin rpy="0.0 0.0 0.0" xyz="0.0 0.0 0.089159"/>
    <axis xyz="0 0 1"/>
    <limit effort="500.0" lower="-3.14159265" upper="3.14159265" velocity="3.15"/>
    <dynamics damping="1.0" friction="0.0"/>
  </joint>
  <link name="l_shoulder_link">
    <visual>
      <geometry>
        <mesh filename="package://tomm_description/meshes/arm/ur5/visual/Shoulder.dae"/>
      </geometry>
      <material name="LightGrey">
        <color rgba="0.7 0.7 0.7 1.0"/>
      </material>
    </visual>
    <collision>
      <geometry>
        <!--mesh filename="package://tomm_description/meshes/arm/ur5/collision/shoulder.stl" /-->
        <cylinder length="0.1" radius="0.065"/>
      </geometry>
    </collision>
    <inertial>
      <mass value="3.7"/>
      <origin rpy="0 0 0" xyz="0.0 0.0 0.0"/>
      <inertia ixx="0.010267495893" ixy="0.0" ixz="0.0" iyy="0.010267495893" iyz="0.0" izz="0.00666"/>
    </inertial>
  </link>
  <joint name="l_shoulder_lift_joint" type="revolute">
    <parent link="l_shoulder_link"/>
    <child link="l_upper_arm_link"/>
    <origin rpy="0.0 1.570796325 0.0" xyz="0.0 0.13585 0.0"/>
    <axis xyz="0 1 0"/>
    <limit effort="500.0" lower="-3.14159265" upper="3.14159265" velocity="3.15"/>
    <dynamics damping="1.0" friction="0.0"/>
  </joint>
  <link name="l_upper_arm_link">
    <visual>
      <geometry>
        <mesh filename="package://tomm_description/meshes/arm/ur5/visual/UpperArm.dae"/>
      </geometry>
      <material name="LightGrey">
        <color rgba="0.7 0.7 0.7 1.0"/>
      </material>
    </visual>
    <collision>
      <geometry>
        <!--mesh filename="package://tomm_description/meshes/arm/ur5/collision/upper_arm.stl" /-->
        <cylinder length="0.535" radius="0.06"/>
      </geometry>
      <origin rpy="0.0 0.0 0.0" xyz="0.0 0.0 0.2125"/>
    </collision>
    <inertial>
      <mass value="8.393"/>
      <origin rpy="0 0 0" xyz="0.0 0.0 0.28"/>
      <inertia ixx="0.22689067591" ixy="0.0" ixz="0.0" iyy="0.22689067591" iyz="0.0" izz="0.0151074"/>
    </inertial>
  </link>
  <joint name="l_elbow_joint" type="revolute">
    <parent link="l_upper_arm_link"/>
    <child link="l_forearm_link"/>
    <origin rpy="0.0 0.0 0.0" xyz="0.0 -0.1197 0.425"/>
    <axis xyz="0 1 0"/>
    <limit effort="500.0" lower="-3.14159265" upper="3.14159265" velocity="3.15"/>
    <dynamics damping="1.0" friction="0.0"/>
  </joint>
  <link name="l_forearm_link">
    <visual>
      <geometry>
        <mesh filename="package://tomm_description/meshes/arm/ur5/visual/Forearm.dae"/>
      </geometry>
      <material name="LightGrey">
        <color rgba="0.7 0.7 0.7 1.0"/>
      </material>
    </visual>
    <collision>
      <geometry>
        <!--mesh filename="package://tomm_description/meshes/arm/ur5/collision/forearm.stl" /-->
        <cylinder length="0.44225" radius="0.04"/>
      </geometry>
      <origin rpy="0.0 0.0 0.0" xyz="0.0 0.0 0.196125"/>
    </collision>
    <inertial>
      <mass value="2.275"/>
      <origin rpy="0 0 0" xyz="0.0 0.0 0.25"/>
      <inertia ixx="0.049443313556" ixy="0.0" ixz="0.0" iyy="0.049443313556" iyz="0.0" izz="0.004095"/>
    </inertial>
  </link>
  <joint name="l_wrist_1_joint" type="revolute">
    <parent link="l_forearm_link"/>
    <child link="l_wrist_1_link"/>
    <origin rpy="0.0 1.570796325 0.0" xyz="0.0 0.0 0.39225"/>
    <axis xyz="0 1 0"/>
    <limit effort="500.0" lower="-3.14159265" upper="3.14159265" velocity="3.2"/>
    <dynamics damping="1.0" friction="0.0"/>
  </joint>
  <link name="l_wrist_1_link">
    <visual>
      <geometry>
        <mesh filename="package://tomm_description/meshes/arm/ur5/visual/Wrist1.dae"/>
      </geometry>
      <material name="LightGrey">
        <color rgba="0.7 0.7 0.7 1.0"/>
      </material>
    </visual>
    <collision>
      <geometry>
        <!--mesh filename="package://tomm_description/meshes/arm/ur5/collision/wrist_1.stl" /-->
        <cylinder length="0.08915" radius="0.04"/>
      </geometry>
      <origin rpy="0.0 0.0 0.0" xyz="0.0 0.08915 0.0"/>
    </collision>
    <inertial>
      <mass value="1.219"/>
      <origin rpy="3.14159265 0 0" xyz="0.0 0.0 0.0"/>
      <inertia ixx="0.111172755531" ixy="0.0" ixz="0.0" iyy="0.111172755531" iyz="0.0" izz="0.21942"/>
    </inertial>
  </link>
  <joint name="l_wrist_2_joint" type="revolute">
    <parent link="l_wrist_1_link"/>
    <child link="l_wrist_2_link"/>
    <origin rpy="0.0 0.0 0.0" xyz="0.0 0.093 0.0"/>
    <axis xyz="0 0 1"/>
    <limit effort="500.0" lower="-3.14159265" upper="3.14159265" velocity="3.2"/>
    <dynamics damping="1.0" friction="0.0"/>
  </joint>
  <link name="l_wrist_2_link">
    <visual>
      <geometry>
        <mesh filename="package://tomm_description/meshes/arm/ur5/visual/Wrist2.dae"/>
      </geometry>
      <material name="LightGrey">
        <color rgba="0.7 0.7 0.7 1.0"/>
      </material>
    </visual>
    <collision>
      <geometry>
        <!--mesh filename="package://tomm_description/meshes/arm/ur5/collision/wrist_2.stl" /-->
        <cylinder length="0.09465" radius="0.04"/>
      </geometry>
      <origin rpy="1.570796325 0.0 0.0" xyz="0.0 -0.01 0.09465"/>
    </collision>
    <inertial>
      <mass value="1.219"/>
      <origin rpy="0 0 0" xyz="0.0 0.0 0.0"/>
      <inertia ixx="0.111172755531" ixy="0.0" ixz="0.0" iyy="0.111172755531" iyz="0.0" izz="0.21942"/>
    </inertial>
  </link>
  <joint name="l_wrist_3_joint" type="revolute">
    <parent link="l_wrist_2_link"/>
    <child link="l_wrist_3_link"/>
    <origin rpy="0.0 0.0 0.0" xyz="0.0 0.0 0.09465"/>
    <axis xyz="0 1 0"/>
    <limit effort="500.0" lower="-3.14159265" upper="3.14159265" velocity="3.2"/>
    <dynamics damping="1.0" friction="0.0"/>
  </joint>
  <link name="l_wrist_3_link">
    <visual>
      <geometry>
        <mesh filename="package://tomm_description/meshes/arm/ur5/visual/Wrist3.dae"/>
      </geometry>
      <material name="LightGrey">
        <color rgba="0.7 0.7 0.7 1.0"/>
      </material>
    </visual>
    <collision>
      <geometry>
        <!--mesh filename="package://tomm_description/meshes/arm/ur5/collision/wrist_3.stl" /-->
        <cylinder length="0.03" radius="0.04"/>
      </geometry>
      <origin rpy="1.570796325 0 0" xyz="0 0.06 0"/>
    </collision>
    <inertial>
      <mass value="0.1879"/>
      <origin rpy="0 0 0" xyz="0.0 0.0 0.0"/>
      <inertia ixx="0.0171364731454" ixy="0.0" ixz="0.0" iyy="0.0171364731454" iyz="0.0" izz="0.033822"/>
    </inertial>
  </link>
  <joint name="l_ee_fixed_joint" type="fixed">
    <parent link="l_wrist_3_link"/>
    <child link="l_ee_link"/>
    <origin rpy="0.0 0.0 1.570796325" xyz="0.0 0.0823 0.0"/>
  </joint>
  <link name="l_ee_link">
    <collision>
      <geometry>
        <box size="0.01 0.01 0.01"/>
      </geometry>
      <origin rpy="0 0 0" xyz="-0.01 0 0"/>
    </collision>
  </link>
  <transmission name="l_shoulder_pan_trans">
    <type>transmission_interface/SimpleTransmission</type>
    <joint name="l_shoulder_pan_joint">
      <hardwareInterface>hardware_interface/PositionJointInterface</hardwareInterface>
    </joint>
    <actuator name="l_shoulder_pan_motor">
      <hardwareInterface>hardware_interface/PositionJointInterface</hardwareInterface>
      <mechanicalReduction>1</mechanicalReduction>
    </actuator>
  </transmission>
  <transmission name="l_shoulder_lift_trans">
    <type>transmission_interface/SimpleTransmission</type>
    <joint name="l_shoulder_lift_joint">
      <hardwareInterface>hardware_interface/PositionJointInterface</hardwareInterface>
    </joint>
    <actuator name="l_shoulder_lift_motor">
      <hardwareInterface>hardware_interface/PositionJointInterface</hardwareInterface>
      <mechanicalReduction>1</mechanicalReduction>
    </actuator>
  </transmission>
  <transmission name="l_elbow_trans">
    <type>transmission_interface/SimpleTransmission</type>
    <joint name="l_elbow_joint">
      <hardwareInterface>hardware_interface/PositionJointInterface</hardwareInterface>
    </joint>
    <actuator name="l_elbow_motor">
      <hardwareInterface>hardware_interface/PositionJointInterface</hardwareInterface>
      <mechanicalReduction>1</mechanicalReduction>
    </actuator>
  </transmission>
  <transmission name="l_wrist_1_trans">
    <type>transmission_interface/SimpleTransmission</type>
    <joint name="l_wrist_1_joint">
      <hardwareInterface>hardware_interface/PositionJointInterface</hardwareInterface>
    </joint>
    <actuator name="l_wrist_1_motor">
      <hardwareInterface>hardware_interface/PositionJointInterface</hardwareInterface>
      <mechanicalReduction>1</mechanicalReduction>
    </actuator>
  </transmission>
  <transmission name="l_wrist_2_trans">
    <type>transmission_interface/SimpleTransmission</type>
    <joint name="l_wrist_2_joint">
      <hardwareInterface>hardware_interface/PositionJointInterface</hardwareInterface>
    </joint>
    <actuator name="l_wrist_2_motor">
      <hardwareInterface>hardware_interface/PositionJointInterface</hardwareInterface>
      <mechanicalReduction>1</mechanicalReduction>
    </actuator>
  </transmission>
  <transmission name="l_wrist_3_trans">
    <type>transmission_interface/SimpleTransmission</type>
    <joint name="l_wrist_3_joint">
      <hardwareInterface>hardware_interface/PositionJointInterface</hardwareInterface>
    </joint>
    <actuator name="l_wrist_3_motor">
      <hardwareInterface>hardware_interface/PositionJointInterface</hardwareInterface>
      <mechanicalReduction>1</mechanicalReduction>
    </actuator>
  </transmission>
  <!-- nothing to do here at the moment -->
  <joint name="torso_to_l_arm" type="fixed">
    <parent link="torso_link"/>
    <child link="l_base_link"/>
    <origin rpy="2.6061 0.6271 -2.6061" xyz="0 0.225 0"/>
  </joint>
  <!-- This is the JR3 adapter -->
  <link name="l_hand_base_adapter_link">
    <visual>
      <origin rpy="1.57079632679 0 1.57079632679" xyz="0 0 -0.045"/>
      <geometry>
        <mesh filename="package://tomm_description/meshes/arm/hand_mount.dae"/>
      </geometry>
    </visual>
    <collision>
      <origin rpy="0 0 0" xyz="0 0 -0.025"/>
      <geometry>
        <cylinder length="0.05" radius="0.035"/>
      </geometry>
    </collision>
  </link>
  <joint name="l_hand_base_adapter_joint" type="fixed">
    <parent link="l_ee_link"/>
    <child link="l_hand_base_adapter_link"/>
    <origin rpy="1.57079632679 0.785 1.57079632679" xyz="0.045 0 0"/>
  </joint>
  <!-- Left arm extensions -->
  <link name="l_strain_relief_box_link">
    <visual>
      <origin rpy="0 3.14159265359 0" xyz="0 0.10 0"/>
      <geometry>
        <mesh filename="package://tomm_description/meshes/arm/Dog-assembly.STL" scale="0.001 0.001 0.001"/>
      </geometry>
      <material name="LightGrey">
        <color rgba="0.7 0.7 0.7 1.0"/>
      </material>
    </visual>
  </link>
  <joint name="l_strain_relief_box_joint" type="fixed">
    <parent link="l_upper_arm_link"/>
    <child link="l_strain_relief_box_link"/>
    <origin rpy="0 0 0" xyz="0 0 0"/>
  </joint>
  <link name="l_cable_rewinder_box_link">
    <visual>
      <origin rpy="0 3.14159265359 0" xyz="0 0.10 0"/>
      <geometry>
        <mesh filename="package://tomm_description/meshes/arm/Coil-assembly.STL" scale="0.001 0.001 0.001"/>
      </geometry>
      <material name="LightGrey">
        <color rgba="0.7 0.7 0.7 1.0"/>
      </material>
    </visual>
  </link>
  <joint name="l_cable_rewinder_box_joint" type="fixed">
    <parent link="l_upper_arm_link"/>
    <child link="l_cable_rewinder_box_link"/>
    <origin rpy="0 0 0" xyz="0 0 0.42"/>
  </joint>
  <link name="l_tunnel_link">
    <visual>
      <origin rpy="1.57079632679 0 -1.57079632679" xyz="0 0 0"/>
      <geometry>
        <mesh filename="package://tomm_description/meshes/arm/Tunnel-assembly.STL" scale="0.001 0.001 0.001"/>
      </geometry>
      <material name="LightGrey">
        <color rgba="0.7 0.7 0.7 1.0"/>
      </material>
    </visual>
  </link>
  <joint name="l_tunnel_joint" type="fixed">
    <parent link="l_upper_arm_link"/>
    <child link="l_tunnel_link"/>
    <origin rpy="0 0 0" xyz="0 -0.005 0.425"/>
  </joint>
  <link name="r_base_link">
    <visual>
      <geometry>
        <mesh filename="package://tomm_description/meshes/arm/ur5/visual/Base.dae"/>
      </geometry>
      <material name="LightGrey">
        <color rgba="0.7 0.7 0.7 1.0"/>
      </material>
    </visual>
    <collision>
      <geometry>
        <!--mesh filename="package://tomm_description/meshes/arm/ur5/collision/base.stl" /-->
        <cylinder length="0.05" radius="0.08"/>
      </geometry>
    </collision>
    <inertial>
      <mass value="4.0"/>
      <origin rpy="0 0 0" xyz="0.0 0.0 0.0"/>
      <inertia ixx="0.00443333156" ixy="0.0" ixz="0.0" iyy="0.00443333156" iyz="0.0" izz="0.0072"/>
    </inertial>
  </link>
  <joint name="r_shoulder_pan_joint" type="revolute">
    <parent link="r_base_link"/>
    <child link="r_shoulder_link"/>
    <origin rpy="0.0 0.0 0.0" xyz="0.0 0.0 0.089159"/>
    <axis xyz="0 0 1"/>
    <limit effort="500.0" lower="-3.14159265" upper="3.14159265" velocity="3.15"/>
    <dynamics damping="1.0" friction="0.0"/>
  </joint>
  <link name="r_shoulder_link">
    <visual>
      <geometry>
        <mesh filename="package://tomm_description/meshes/arm/ur5/visual/Shoulder.dae"/>
      </geometry>
      <material name="LightGrey">
        <color rgba="0.7 0.7 0.7 1.0"/>
      </material>
    </visual>
    <collision>
      <geometry>
        <!--mesh filename="package://tomm_description/meshes/arm/ur5/collision/shoulder.stl" /-->
        <cylinder length="0.1" radius="0.065"/>
      </geometry>
    </collision>
    <inertial>
      <mass value="3.7"/>
      <origin rpy="0 0 0" xyz="0.0 0.0 0.0"/>
      <inertia ixx="0.010267495893" ixy="0.0" ixz="0.0" iyy="0.010267495893" iyz="0.0" izz="0.00666"/>
    </inertial>
  </link>
  <joint name="r_shoulder_lift_joint" type="revolute">
    <parent link="r_shoulder_link"/>
    <child link="r_upper_arm_link"/>
    <origin rpy="0.0 1.570796325 0.0" xyz="0.0 0.13585 0.0"/>
    <axis xyz="0 1 0"/>
    <limit effort="500.0" lower="-3.14159265" upper="3.14159265" velocity="3.15"/>
    <dynamics damping="1.0" friction="0.0"/>
  </joint>
  <link name="r_upper_arm_link">
    <visual>
      <geometry>
        <mesh filename="package://tomm_description/meshes/arm/ur5/visual/UpperArm.dae"/>
      </geometry>
      <material name="LightGrey">
        <color rgba="0.7 0.7 0.7 1.0"/>
      </material>
    </visual>
    <collision>
      <geometry>
        <!--mesh filename="package://tomm_description/meshes/arm/ur5/collision/upper_arm.stl" /-->
        <cylinder length="0.535" radius="0.06"/>
      </geometry>
      <origin rpy="0.0 0.0 0.0" xyz="0.0 0.0 0.2125"/>
    </collision>
    <inertial>
      <mass value="8.393"/>
      <origin rpy="0 0 0" xyz="0.0 0.0 0.28"/>
      <inertia ixx="0.22689067591" ixy="0.0" ixz="0.0" iyy="0.22689067591" iyz="0.0" izz="0.0151074"/>
    </inertial>
  </link>
  <joint name="r_elbow_joint" type="revolute">
    <parent link="r_upper_arm_link"/>
    <child link="r_forearm_link"/>
    <origin rpy="0.0 0.0 0.0" xyz="0.0 -0.1197 0.425"/>
    <axis xyz="0 1 0"/>
    <limit effort="500.0" lower="-3.14159265" upper="3.14159265" velocity="3.15"/>
    <dynamics damping="1.0" friction="0.0"/>
  </joint>
  <link name="r_forearm_link">
    <visual>
      <geometry>
        <mesh filename="package://tomm_description/meshes/arm/ur5/visual/Forearm.dae"/>
      </geometry>
      <material name="LightGrey">
        <color rgba="0.7 0.7 0.7 1.0"/>
      </material>
    </visual>
    <collision>
      <geometry>
        <!--mesh filename="package://tomm_description/meshes/arm/ur5/collision/forearm.stl" /-->
        <cylinder length="0.44225" radius="0.04"/>
      </geometry>
      <origin rpy="0.0 0.0 0.0" xyz="0.0 0.0 0.196125"/>
    </collision>
    <inertial>
      <mass value="2.275"/>
      <origin rpy="0 0 0" xyz="0.0 0.0 0.25"/>
      <inertia ixx="0.049443313556" ixy="0.0" ixz="0.0" iyy="0.049443313556" iyz="0.0" izz="0.004095"/>
    </inertial>
  </link>
  <joint name="r_wrist_1_joint" type="revolute">
    <parent link="r_forearm_link"/>
    <child link="r_wrist_1_link"/>
    <origin rpy="0.0 1.570796325 0.0" xyz="0.0 0.0 0.39225"/>
    <axis xyz="0 1 0"/>
    <limit effort="500.0" lower="-3.14159265" upper="3.14159265" velocity="3.2"/>
    <dynamics damping="1.0" friction="0.0"/>
  </joint>
  <link name="r_wrist_1_link">
    <visual>
      <geometry>
        <mesh filename="package://tomm_description/meshes/arm/ur5/visual/Wrist1.dae"/>
      </geometry>
      <material name="LightGrey">
        <color rgba="0.7 0.7 0.7 1.0"/>
      </material>
    </visual>
    <collision>
      <geometry>
        <!--mesh filename="package://tomm_description/meshes/arm/ur5/collision/wrist_1.stl" /-->
        <cylinder length="0.08915" radius="0.04"/>
      </geometry>
      <origin rpy="0.0 0.0 0.0" xyz="0.0 0.08915 0.0"/>
    </collision>
    <inertial>
      <mass value="1.219"/>
      <origin rpy="3.14159265 0 0" xyz="0.0 0.0 0.0"/>
      <inertia ixx="0.111172755531" ixy="0.0" ixz="0.0" iyy="0.111172755531" iyz="0.0" izz="0.21942"/>
    </inertial>
  </link>
  <joint name="r_wrist_2_joint" type="revolute">
    <parent link="r_wrist_1_link"/>
    <child link="r_wrist_2_link"/>
    <origin rpy="0.0 0.0 0.0" xyz="0.0 0.093 0.0"/>
    <axis xyz="0 0 1"/>
    <limit effort="500.0" lower="-3.14159265" upper="3.14159265" velocity="3.2"/>
    <dynamics damping="1.0" friction="0.0"/>
  </joint>
  <link name="r_wrist_2_link">
    <visual>
      <geometry>
        <mesh filename="package://tomm_description/meshes/arm/ur5/visual/Wrist2.dae"/>
      </geometry>
      <material name="LightGrey">
        <color rgba="0.7 0.7 0.7 1.0"/>
      </material>
    </visual>
    <collision>
      <geometry>
        <!--mesh filename="package://tomm_description/meshes/arm/ur5/collision/wrist_2.stl" /-->
        <cylinder length="0.09465" radius="0.04"/>
      </geometry>
      <origin rpy="1.570796325 0.0 0.0" xyz="0.0 -0.01 0.09465"/>
    </collision>
    <inertial>
      <mass value="1.219"/>
      <origin rpy="0 0 0" xyz="0.0 0.0 0.0"/>
      <inertia ixx="0.111172755531" ixy="0.0" ixz="0.0" iyy="0.111172755531" iyz="0.0" izz="0.21942"/>
    </inertial>
  </link>
  <joint name="r_wrist_3_joint" type="revolute">
    <parent link="r_wrist_2_link"/>
    <child link="r_wrist_3_link"/>
    <origin rpy="0.0 0.0 0.0" xyz="0.0 0.0 0.09465"/>
    <axis xyz="0 1 0"/>
    <limit effort="500.0" lower="-3.14159265" upper="3.14159265" velocity="3.2"/>
    <dynamics damping="1.0" friction="0.0"/>
  </joint>
  <link name="r_wrist_3_link">
    <visual>
      <geometry>
        <mesh filename="package://tomm_description/meshes/arm/ur5/visual/Wrist3.dae"/>
      </geometry>
      <material name="LightGrey">
        <color rgba="0.7 0.7 0.7 1.0"/>
      </material>
    </visual>
    <collision>
      <geometry>
        <!--mesh filename="package://tomm_description/meshes/arm/ur5/collision/wrist_3.stl" /-->
        <cylinder length="0.03" radius="0.04"/>
      </geometry>
      <origin rpy="1.570796325 0 0" xyz="0 0.06 0"/>
    </collision>
    <inertial>
      <mass value="0.1879"/>
      <origin rpy="0 0 0" xyz="0.0 0.0 0.0"/>
      <inertia ixx="0.0171364731454" ixy="0.0" ixz="0.0" iyy="0.0171364731454" iyz="0.0" izz="0.033822"/>
    </inertial>
  </link>
  <joint name="r_ee_fixed_joint" type="fixed">
    <parent link="r_wrist_3_link"/>
    <child link="r_ee_link"/>
    <origin rpy="0.0 0.0 1.570796325" xyz="0.0 0.0823 0.0"/>
  </joint>
  <link name="r_ee_link">
    <collision>
      <geometry>
        <box size="0.01 0.01 0.01"/>
      </geometry>
      <origin rpy="0 0 0" xyz="-0.01 0 0"/>
    </collision>
  </link>
  <transmission name="r_shoulder_pan_trans">
    <type>transmission_interface/SimpleTransmission</type>
    <joint name="r_shoulder_pan_joint">
      <hardwareInterface>hardware_interface/PositionJointInterface</hardwareInterface>
    </joint>
    <actuator name="r_shoulder_pan_motor">
      <hardwareInterface>hardware_interface/PositionJointInterface</hardwareInterface>
      <mechanicalReduction>1</mechanicalReduction>
    </actuator>
  </transmission>
  <transmission name="r_shoulder_lift_trans">
    <type>transmission_interface/SimpleTransmission</type>
    <joint name="r_shoulder_lift_joint">
      <hardwareInterface>hardware_interface/PositionJointInterface</hardwareInterface>
    </joint>
    <actuator name="r_shoulder_lift_motor">
      <hardwareInterface>hardware_interface/PositionJointInterface</hardwareInterface>
      <mechanicalReduction>1</mechanicalReduction>
    </actuator>
  </transmission>
  <transmission name="r_elbow_trans">
    <type>transmission_interface/SimpleTransmission</type>
    <joint name="r_elbow_joint">
      <hardwareInterface>hardware_interface/PositionJointInterface</hardwareInterface>
    </joint>
    <actuator name="r_elbow_motor">
      <hardwareInterface>hardware_interface/PositionJointInterface</hardwareInterface>
      <mechanicalReduction>1</mechanicalReduction>
    </actuator>
  </transmission>
  <transmission name="r_wrist_1_trans">
    <type>transmission_interface/SimpleTransmission</type>
    <joint name="r_wrist_1_joint">
      <hardwareInterface>hardware_interface/PositionJointInterface</hardwareInterface>
    </joint>
    <actuator name="r_wrist_1_motor">
      <hardwareInterface>hardware_interface/PositionJointInterface</hardwareInterface>
      <mechanicalReduction>1</mechanicalReduction>
    </actuator>
  </transmission>
  <transmission name="r_wrist_2_trans">
    <type>transmission_interface/SimpleTransmission</type>
    <joint name="r_wrist_2_joint">
      <hardwareInterface>hardware_interface/PositionJointInterface</hardwareInterface>
    </joint>
    <actuator name="r_wrist_2_motor">
      <hardwareInterface>hardware_interface/PositionJointInterface</hardwareInterface>
      <mechanicalReduction>1</mechanicalReduction>
    </actuator>
  </transmission>
  <transmission name="r_wrist_3_trans">
    <type>transmission_interface/SimpleTransmission</type>
    <joint name="r_wrist_3_joint">
      <hardwareInterface>hardware_interface/PositionJointInterface</hardwareInterface>
    </joint>
    <actuator name="r_wrist_3_motor">
      <hardwareInterface>hardware_interface/PositionJointInterface</hardwareInterface>
      <mechanicalReduction>1</mechanicalReduction>
    </actuator>
  </transmission>
  <joint name="torso_to_r_arm" type="fixed">
    <parent link="torso_link"/>
    <child link="r_base_link"/>
    <origin rpy="2.6061 -0.6271 -0.5355" xyz="0 -0.225 0"/>
  </joint>
  <!-- This is the JR3 adapter -->
  <link name="r_hand_base_adapter_link">
    <visual>
      <origin rpy="1.57079632679 0 1.57079632679" xyz="0 0 -0.045"/>
      <geometry>
        <mesh filename="package://tomm_description/meshes/arm/hand_mount.dae"/>
      </geometry>
    </visual>
    <collision>
      <origin rpy="0 0 0" xyz="0 0 -0.025"/>
      <geometry>
        <cylinder length="0.05" radius="0.035"/>
      </geometry>
    </collision>
  </link>
  <joint name="r_hand_base_adapter_joint" type="fixed">
    <parent link="r_ee_link"/>
    <child link="r_hand_base_adapter_link"/>
    <origin rpy="1.57079632679 2.356 1.57079632679" xyz="0.045 0 0"/>
  </joint>
  <!-- BASE -->
  <link name="l_hand_base_link">
    <visual>
      <geometry>
        <mesh filename="package://tomm_description/meshes/hand/base_link_left.STL"/>
      </geometry>
      <!-- LEFT -->
      <origin rpy="-1.5707963259 0 0" xyz="0 0 0 "/>
      <!-- RIGHT -->
      <!--<origin rpy="0 0 0" xyz="0 0 0 "/>-->
      <material name="black">
        <color rgba="0.2 0.2 0.2 1"/>
      </material>
    </visual>
    <collision>
      <origin rpy="0 0 0" xyz="-0.009300 0 -0.0475"/>
      <geometry>
        <box size="0.0408 0.1130 0.095"/>
      </geometry>
    </collision>
    <inertial>
      <origin rpy="0 0 0" xyz="0 0 0.0475"/>
      <mass value="0.4154"/>
      <inertia ixx="1e-4" ixy="0.0" ixz="0.0" iyy="1e-4" iyz="0.0" izz="1e-4"/>
    </inertial>
  </link>
  <!-- ============================================================================= -->
  <!-- FINGERS -->
  <!-- [LINK 0, 4, 8] -->
  <link name="l_hand_link_ring_0">
    <visual>
      <geometry>
        <mesh filename="package://tomm_description/meshes/hand/link_0.0.STL"/>
      </geometry>
      <material name="black"/>
    </visual>
    <collision>
      <geometry>
        <box size="0.0196 0.0275 0.0164"/>
      </geometry>
      <origin rpy="0 0 0" xyz="0 0 0.0082"/>
    </collision>
    <inertial>
      <mass value="0.0119"/>
      <origin rpy="0 0 0" xyz="0 0 0"/>
      <inertia ixx="1.01666658333e-06" ixy="0.0" ixz="0.0" iyy="6.47677333333e-07" iyz="0.0" izz="1.01666658333e-06"/>
    </inertial>
  </link>
  <joint name="l_hand_joint_ring_0" type="fixed">
    <axis xyz="0 0 1"/>
    <limit effort="0" lower="-0.47" upper="0.47" velocity="0"/>
    <parent link="l_hand_base_link"/>
    <child link="l_hand_link_ring_0"/>
    <origin rpy="-0.08726646255 0 0" xyz="0 0.0435 -0.001542"/>
  </joint>
  <!-- [LINK 1, 5, 9] -->
  <link name="l_hand_link_ring_1">
    <visual>
      <geometry>
        <mesh filename="package://tomm_description/meshes/hand/link_1.0.STL"/>
      </geometry>
      <material name="black"/>
    </visual>
    <collision>
      <geometry>
        <box size="0.0196 0.0275 0.054"/>
      </geometry>
      <origin rpy="0 0 0" xyz="0 0 0.027"/>
    </collision>
    <inertial>
      <mass value="0.065"/>
      <origin rpy="0 0 0" xyz="0 0 0"/>
      <inertia ixx="7.95654166667e-05" ixy="1.7199e-05" ixz="8.75875e-06" iyy="2.47088833333e-05" iyz="2.413125e-05" izz="7.95654166667e-05"/>
    </inertial>
  </link>
  <joint name="l_hand_joint_ring_1" type="fixed">
    <limit effort="0" lower="-0.196" upper="1.61" velocity="0"/>
    <axis xyz="0 1 0"/>
    <parent link="l_hand_link_ring_0"/>
    <child link="l_hand_link_ring_1"/>
    <origin xyz="0 0 0.0164"/>
  </joint>
  <!-- [LINK 2, 6, 10]-->
  <link name="l_hand_link_ring_2">
    <visual>
      <geometry>
        <mesh filename="package://tomm_description/meshes/hand/link_2.0.STL"/>
      </geometry>
      <material name="black"/>
    </visual>
    <collision>
      <geometry>
        <box size="0.0196 0.0275 0.0384"/>
      </geometry>
      <origin rpy="0 0 0" xyz="0 0 0.0192"/>
    </collision>
    <inertial>
      <mass value="0.0355"/>
      <origin rpy="0 0 0" xyz="0 0 0"/>
      <inertia ixx="2.63979183333e-05" ixy="6.67968e-06" ixz="4.783625e-06" iyy="1.34948516667e-05" iyz="9.372e-06" izz="2.63979183333e-05"/>
    </inertial>
  </link>
  <joint name="l_hand_joint_ring_2" type="fixed">
    <axis xyz="0 1 0"/>
    <limit effort="0" lower="-0.174" upper="1.709" velocity="0"/>
    <parent link="l_hand_link_ring_1"/>
    <child link="l_hand_link_ring_2"/>
    <origin xyz="0 0 0.054"/>
  </joint>
  <!-- [LINK 3, 7, 11] -->
  <link name="l_hand_link_ring_3">
    <visual>
      <geometry>
        <mesh filename="package://tomm_description/meshes/hand/link_3.0.STL"/>
      </geometry>
      <material name="black"/>
    </visual>
    <collision>
      <geometry>
        <box size="0.0196 0.0275 0.0267"/>
      </geometry>
      <origin rpy="0 0 0" xyz="0 0 0.01335"/>
    </collision>
    <inertial>
      <mass value="0.0096"/>
      <origin rpy="0 0 0" xyz="0 0 0"/>
      <inertia ixx="4.701248e-06" ixy="1.255968e-06" ixz="1.2936e-06" iyy="3.649312e-06" iyz="1.7622e-06" izz="4.701248e-06"/>
    </inertial>
  </link>
  <joint name="l_hand_joint_ring_3" type="fixed">
    <axis xyz="0 1 0"/>
    <limit effort="0" lower="-0.227" upper="1.618" velocity="0"/>
    <parent link="l_hand_link_ring_2"/>
    <child link="l_hand_link_ring_3"/>
    <origin xyz="0 0 0.0384"/>
  </joint>
  <!-- [FINGER TIP] -->
  <link name="l_hand_link_ring_3_tip">
    <visual>
      <geometry>
        <mesh filename="package://tomm_description/meshes/hand/link_3.0_tip.STL"/>
      </geometry>
      <material name="white">
        <color rgba=".9 .9 .9 1"/>
      </material>
    </visual>
    <collision>
      <geometry>
        <sphere radius="0.012"/>
      </geometry>
    </collision>
    <inertial>
      <mass value="0.0168"/>
      <origin rpy="0 0 0" xyz="0 0 0"/>
      <inertia ixx="9.68e-07" ixy="0" ixz="0" iyy="9.68e-07" iyz="0" izz="9.68e-07"/>
    </inertial>
  </link>
  <joint name="l_hand_joint_ring_3_tip" type="fixed">
    <parent link="l_hand_link_ring_3"/>
    <child link="l_hand_link_ring_3_tip"/>
    <origin rpy="0 0 0" xyz="0 0 0.0267"/>
  </joint>
  <!-- <xacro:finger_transmission prefix="${prefix}" finger_label="${finger_label}"/>  -->
  <!-- <xacro:allegro_hand_gazebo prefix="${prefix}" finger_label="${finger_label}"/>  -->
  <!-- [LINK 0, 4, 8] -->
  <link name="l_hand_link_middle_0">
    <visual>
      <geometry>
        <mesh filename="package://tomm_description/meshes/hand/link_0.0.STL"/>
      </geometry>
      <material name="black"/>
    </visual>
    <collision>
      <geometry>
        <box size="0.0196 0.0275 0.0164"/>
      </geometry>
      <origin rpy="0 0 0" xyz="0 0 0.0082"/>
    </collision>
    <inertial>
      <mass value="0.0119"/>
      <origin rpy="0 0 0" xyz="0 0 0"/>
      <inertia ixx="1.01666658333e-06" ixy="0.0" ixz="0.0" iyy="6.47677333333e-07" iyz="0.0" izz="1.01666658333e-06"/>
    </inertial>
  </link>
  <joint name="l_hand_joint_middle_0" type="fixed">
    <axis xyz="0 0 1"/>
    <limit effort="0" lower="-0.47" upper="0.47" velocity="0"/>
    <parent link="l_hand_base_link"/>
    <child link="l_hand_link_middle_0"/>
    <origin rpy="0.0 0 0" xyz="0 0 0.0007"/>
  </joint>
  <!-- [LINK 1, 5, 9] -->
  <link name="l_hand_link_middle_1">
    <visual>
      <geometry>
        <mesh filename="package://tomm_description/meshes/hand/link_1.0.STL"/>
      </geometry>
      <material name="black"/>
    </visual>
    <collision>
      <geometry>
        <box size="0.0196 0.0275 0.054"/>
      </geometry>
      <origin rpy="0 0 0" xyz="0 0 0.027"/>
    </collision>
    <inertial>
      <mass value="0.065"/>
      <origin rpy="0 0 0" xyz="0 0 0"/>
      <inertia ixx="7.95654166667e-05" ixy="1.7199e-05" ixz="8.75875e-06" iyy="2.47088833333e-05" iyz="2.413125e-05" izz="7.95654166667e-05"/>
    </inertial>
  </link>
  <joint name="l_hand_joint_middle_1" type="fixed">
    <limit effort="0" lower="-0.196" upper="1.61" velocity="0"/>
    <axis xyz="0 1 0"/>
    <parent link="l_hand_link_middle_0"/>
    <child link="l_hand_link_middle_1"/>
    <origin xyz="0 0 0.0164"/>
  </joint>
  <!-- [LINK 2, 6, 10]-->
  <link name="l_hand_link_middle_2">
    <visual>
      <geometry>
        <mesh filename="package://tomm_description/meshes/hand/link_2.0.STL"/>
      </geometry>
      <material name="black"/>
    </visual>
    <collision>
      <geometry>
        <box size="0.0196 0.0275 0.0384"/>
      </geometry>
      <origin rpy="0 0 0" xyz="0 0 0.0192"/>
    </collision>
    <inertial>
      <mass value="0.0355"/>
      <origin rpy="0 0 0" xyz="0 0 0"/>
      <inertia ixx="2.63979183333e-05" ixy="6.67968e-06" ixz="4.783625e-06" iyy="1.34948516667e-05" iyz="9.372e-06" izz="2.63979183333e-05"/>
    </inertial>
  </link>
  <joint name="l_hand_joint_middle_2" type="fixed">
    <axis xyz="0 1 0"/>
    <limit effort="0" lower="-0.174" upper="1.709" velocity="0"/>
    <parent link="l_hand_link_middle_1"/>
    <child link="l_hand_link_middle_2"/>
    <origin xyz="0 0 0.054"/>
  </joint>
  <!-- [LINK 3, 7, 11] -->
  <link name="l_hand_link_middle_3">
    <visual>
      <geometry>
        <mesh filename="package://tomm_description/meshes/hand/link_3.0.STL"/>
      </geometry>
      <material name="black"/>
    </visual>
    <collision>
      <geometry>
        <box size="0.0196 0.0275 0.0267"/>
      </geometry>
      <origin rpy="0 0 0" xyz="0 0 0.01335"/>
    </collision>
    <inertial>
      <mass value="0.0096"/>
      <origin rpy="0 0 0" xyz="0 0 0"/>
      <inertia ixx="4.701248e-06" ixy="1.255968e-06" ixz="1.2936e-06" iyy="3.649312e-06" iyz="1.7622e-06" izz="4.701248e-06"/>
    </inertial>
  </link>
  <joint name="l_hand_joint_middle_3" type="fixed">
    <axis xyz="0 1 0"/>
    <limit effort="0" lower="-0.227" upper="1.618" velocity="0"/>
    <parent link="l_hand_link_middle_2"/>
    <child link="l_hand_link_middle_3"/>
    <origin xyz="0 0 0.0384"/>
  </joint>
  <!-- [FINGER TIP] -->
  <link name="l_hand_link_middle_3_tip">
    <visual>
      <geometry>
        <mesh filename="package://tomm_description/meshes/hand/link_3.0_tip.STL"/>
      </geometry>
      <material name="white">
        <color rgba=".9 .9 .9 1"/>
      </material>
    </visual>
    <collision>
      <geometry>
        <sphere radius="0.012"/>
      </geometry>
    </collision>
    <inertial>
      <mass value="0.0168"/>
      <origin rpy="0 0 0" xyz="0 0 0"/>
      <inertia ixx="9.68e-07" ixy="0" ixz="0" iyy="9.68e-07" iyz="0" izz="9.68e-07"/>
    </inertial>
  </link>
  <joint name="l_hand_joint_middle_3_tip" type="fixed">
    <parent link="l_hand_link_middle_3"/>
    <child link="l_hand_link_middle_3_tip"/>
    <origin rpy="0 0 0" xyz="0 0 0.0267"/>
  </joint>
  <!-- <xacro:finger_transmission prefix="${prefix}" finger_label="${finger_label}"/>  -->
  <!-- <xacro:allegro_hand_gazebo prefix="${prefix}" finger_label="${finger_label}"/>  -->
  <!-- [LINK 0, 4, 8] -->
  <link name="l_hand_link_index_0">
    <visual>
      <geometry>
        <mesh filename="package://tomm_description/meshes/hand/link_0.0.STL"/>
      </geometry>
      <material name="black"/>
    </visual>
    <collision>
      <geometry>
        <box size="0.0196 0.0275 0.0164"/>
      </geometry>
      <origin rpy="0 0 0" xyz="0 0 0.0082"/>
    </collision>
    <inertial>
      <mass value="0.0119"/>
      <origin rpy="0 0 0" xyz="0 0 0"/>
      <inertia ixx="1.01666658333e-06" ixy="0.0" ixz="0.0" iyy="6.47677333333e-07" iyz="0.0" izz="1.01666658333e-06"/>
    </inertial>
  </link>
  <joint name="l_hand_joint_index_0" type="fixed">
    <axis xyz="0 0 1"/>
    <limit effort="0" lower="-0.47" upper="0.47" velocity="0"/>
    <parent link="l_hand_base_link"/>
    <child link="l_hand_link_index_0"/>
    <origin rpy="0.08726646255 0 0" xyz="0 -0.0435 -0.001542"/>
  </joint>
  <!-- [LINK 1, 5, 9] -->
  <link name="l_hand_link_index_1">
    <visual>
      <geometry>
        <mesh filename="package://tomm_description/meshes/hand/link_1.0.STL"/>
      </geometry>
      <material name="black"/>
    </visual>
    <collision>
      <geometry>
        <box size="0.0196 0.0275 0.054"/>
      </geometry>
      <origin rpy="0 0 0" xyz="0 0 0.027"/>
    </collision>
    <inertial>
      <mass value="0.065"/>
      <origin rpy="0 0 0" xyz="0 0 0"/>
      <inertia ixx="7.95654166667e-05" ixy="1.7199e-05" ixz="8.75875e-06" iyy="2.47088833333e-05" iyz="2.413125e-05" izz="7.95654166667e-05"/>
    </inertial>
  </link>
  <joint name="l_hand_joint_index_1" type="fixed">
    <limit effort="0" lower="-0.196" upper="1.61" velocity="0"/>
    <axis xyz="0 1 0"/>
    <parent link="l_hand_link_index_0"/>
    <child link="l_hand_link_index_1"/>
    <origin xyz="0 0 0.0164"/>
  </joint>
  <!-- [LINK 2, 6, 10]-->
  <link name="l_hand_link_index_2">
    <visual>
      <geometry>
        <mesh filename="package://tomm_description/meshes/hand/link_2.0.STL"/>
      </geometry>
      <material name="black"/>
    </visual>
    <collision>
      <geometry>
        <box size="0.0196 0.0275 0.0384"/>
      </geometry>
      <origin rpy="0 0 0" xyz="0 0 0.0192"/>
    </collision>
    <inertial>
      <mass value="0.0355"/>
      <origin rpy="0 0 0" xyz="0 0 0"/>
      <inertia ixx="2.63979183333e-05" ixy="6.67968e-06" ixz="4.783625e-06" iyy="1.34948516667e-05" iyz="9.372e-06" izz="2.63979183333e-05"/>
    </inertial>
  </link>
  <joint name="l_hand_joint_index_2" type="fixed">
    <axis xyz="0 1 0"/>
    <limit effort="0" lower="-0.174" upper="1.709" velocity="0"/>
    <parent link="l_hand_link_index_1"/>
    <child link="l_hand_link_index_2"/>
    <origin xyz="0 0 0.054"/>
  </joint>
  <!-- [LINK 3, 7, 11] -->
  <link name="l_hand_link_index_3">
    <visual>
      <geometry>
        <mesh filename="package://tomm_description/meshes/hand/link_3.0.STL"/>
      </geometry>
      <material name="black"/>
    </visual>
    <collision>
      <geometry>
        <box size="0.0196 0.0275 0.0267"/>
      </geometry>
      <origin rpy="0 0 0" xyz="0 0 0.01335"/>
    </collision>
    <inertial>
      <mass value="0.0096"/>
      <origin rpy="0 0 0" xyz="0 0 0"/>
      <inertia ixx="4.701248e-06" ixy="1.255968e-06" ixz="1.2936e-06" iyy="3.649312e-06" iyz="1.7622e-06" izz="4.701248e-06"/>
    </inertial>
  </link>
  <joint name="l_hand_joint_index_3" type="fixed">
    <axis xyz="0 1 0"/>
    <limit effort="0" lower="-0.227" upper="1.618" velocity="0"/>
    <parent link="l_hand_link_index_2"/>
    <child link="l_hand_link_index_3"/>
    <origin xyz="0 0 0.0384"/>
  </joint>
  <!-- [FINGER TIP] -->
  <link name="l_hand_link_index_3_tip">
    <visual>
      <geometry>
        <mesh filename="package://tomm_description/meshes/hand/link_3.0_tip.STL"/>
      </geometry>
      <material name="white">
        <color rgba=".9 .9 .9 1"/>
      </material>
    </visual>
    <collision>
      <geometry>
        <sphere radius="0.012"/>
      </geometry>
    </collision>
    <inertial>
      <mass value="0.0168"/>
      <origin rpy="0 0 0" xyz="0 0 0"/>
      <inertia ixx="9.68e-07" ixy="0" ixz="0" iyy="9.68e-07" iyz="0" izz="9.68e-07"/>
    </inertial>
  </link>
  <joint name="l_hand_joint_index_3_tip" type="fixed">
    <parent link="l_hand_link_index_3"/>
    <child link="l_hand_link_index_3_tip"/>
    <origin rpy="0 0 0" xyz="0 0 0.0267"/>
  </joint>
  <!-- <xacro:finger_transmission prefix="${prefix}" finger_label="${finger_label}"/>  -->
  <!-- <xacro:allegro_hand_gazebo prefix="${prefix}" finger_label="${finger_label}"/>  -->
  <!-- [LINK 12] -->
  <link name="l_hand_link_thumb_0">
    <visual>
      <geometry>
        <mesh filename="package://tomm_description/meshes/hand/link_12.0_left.STL"/>
      </geometry>
      <material name="black">
        <color rgba=".2 .2 .2 1"/>
      </material>
      <origin rpy="3.1415926518 0 0" xyz="0 0 0"/>
    </visual>
    <collision>
      <geometry>
        <box size="0.0358 0.034 0.0455"/>
      </geometry>
      <origin rpy="0 0 0" xyz="-0.0179 -0.009 0.0145"/>
    </collision>
    <inertial>
      <mass value="0.0176"/>
      <origin rpy="0 0 0" xyz="0 0 0"/>
      <inertia ixx="1.89273333333e-5" ixy="7.16716e-06" ixz="5.35568e-06" iyy="1.43008213333e-05" iyz="6.8068e-06" izz="1.89273333333e-05"/>
    </inertial>
  </link>
  <joint name="l_hand_joint_thumb_0" type="fixed">
    <axis xyz="+1 0 0"/>
    <limit effort="0" lower="0.263" upper="1.396" velocity="0"/>
    <parent link="l_hand_base_link"/>
    <child link="l_hand_link_thumb_0"/>
    <origin rpy="0 -1.65806278845 1.5707963259" xyz="-0.0182 -0.019333 -0.045987"/>
  </joint>
  <!-- [LINK 13] -->
  <link name="l_hand_link_thumb_1">
    <visual>
      <geometry>
        <mesh filename="package://tomm_description/meshes/hand/link_13.0.STL"/>
      </geometry>
      <material name="black">
        <color rgba=".2 .2 .2 1"/>
      </material>
    </visual>
    <collision>
      <geometry>
        <box size="0.0196 0.0275 0.0177"/>
      </geometry>
      <origin rpy="0 0 0" xyz="0 0 0.00885"/>
    </collision>
    <inertial>
      <mass value="0.0119"/>
      <origin rpy="0 0 0" xyz="0 0 0"/>
      <inertia ixx="4.24250866667e-06" ixy="1.032087e-06" ixz="1.603525e-06" iyy="4.52362633333e-06" iyz="1.44808125e-06" izz="4.24250866667e-06"/>
    </inertial>
  </link>
  <joint name="l_hand_joint_thumb_1" type="fixed">
    <axis xyz="0 0 -1"/>
    <limit effort="0" lower="-0.105" upper="1.163" velocity="0"/>
    <parent link="l_hand_link_thumb_0"/>
    <child link="l_hand_link_thumb_1"/>
    <!-- RIGHT -->
    <!-- <origin xyz="-0.027 0.005 0.0399"/> -->
    <!-- LEFT -->
    <origin xyz="-0.027 -0.005 0.0399"/>
  </joint>
  <!-- [LINK 14] -->
  <link name="l_hand_link_thumb_2">
    <visual>
      <geometry>
        <mesh filename="package://tomm_description/meshes/hand/link_14.0.STL"/>
      </geometry>
      <material name="black">
		  	</material>
    </visual>
    <collision>
      <geometry>
        <box size="0.0196 0.0275 0.0514"/>
      </geometry>
      <origin rpy="0 0 0" xyz="0 0 0.0257"/>
    </collision>
    <inertial>
      <mass value="0.038"/>
      <origin rpy="0 0 0" xyz="0 0 0"/>
      <inertia ixx="4.30439933333e-05" ixy="9.57068e-06" ixz="5.1205e-06" iyy="1.44451933333e-05" iyz="1.342825e-05" izz="4.30439933333e-05"/>
    </inertial>
  </link>
  <joint name="l_hand_joint_thumb_2" type="fixed">
    <axis xyz="0 1 0"/>
    <limit effort="0" lower="-0.189" upper="1.644" velocity="0"/>
    <parent link="l_hand_link_thumb_1"/>
    <child link="l_hand_link_thumb_2"/>
    <origin xyz="0 0 0.0177"/>
  </joint>
  <!-- [LINK 15] -->
  <link name="l_hand_link_thumb_3">
    <visual>
      <geometry>
        <mesh filename="package://tomm_description/meshes/hand/link_15.0.STL"/>
      </geometry>
      <material name="black">
    	</material>
    </visual>
    <collision>
      <geometry>
        <box size="0.0196 0.0275 0.0423"/>
      </geometry>
      <origin rpy="0 0 0" xyz="0 0 0.02115"/>
    </collision>
    <inertial>
      <mass value="0.0388"/>
      <origin rpy="0 0 0" xyz="0 0 0"/>
      <inertia ixx="3.29223173333e-05" ixy="8.042076e-06" ixz="5.2283e-06" iyy="1.47493026667e-5" iyz="1.1283525e-5" izz="3.29223173333e-05"/>
    </inertial>
  </link>
  <joint name="l_hand_joint_thumb_3" type="fixed">
    <axis xyz="0 1 0"/>
    <limit effort="0" lower="-0.162" upper="1.719" velocity="0"/>
    <parent link="l_hand_link_thumb_2"/>
    <child link="l_hand_link_thumb_3"/>
    <origin xyz="0 0 0.0514"/>
  </joint>
  <!-- [FINGER TIP] -->
  <link name="l_hand_link_thumb_3_tip">
    <visual>
      <geometry>
        <mesh filename="package://tomm_description/meshes/hand/link_15.0_tip.STL"/>
      </geometry>
      <material name="white">
        <color rgba=".9 .9 .9 1"/>
      </material>
    </visual>
    <collision>
      <geometry>
        <sphere radius="0.012"/>
      </geometry>
      <origin rpy="0 0 0" xyz="0 0 0"/>
    </collision>
    <inertial>
      <mass value="0.0168"/>
      <origin rpy="0 0 0" xyz="0 0 0"/>
      <inertia ixx="9.68e-07" ixy="0" ixz="0" iyy="9.68e-07" iyz="0" izz="9.68e-07"/>
    </inertial>
  </link>
  <joint name="l_hand_joint_thumb_3_tip" type="fixed">
    <parent link="l_hand_link_thumb_3"/>
    <child link="l_hand_link_thumb_3_tip"/>
    <origin rpy="0 0 0" xyz="0 0 0.0423"/>
    <!--0.0267000000000005-->
  </joint>
  <!-- <xacro:finger_transmission prefix="${prefix}" finger_label="${finger_label}"/>  -->
  <!-- <xacro:allegro_hand_gazebo prefix="${prefix}" finger_label="${finger_label}"/>  -->
  <joint name="l_hand_base_joint" type="fixed">
    <parent link="l_hand_base_adapter_link"/>
    <child link="l_hand_base_link"/>
    <origin rpy="0 0 0" xyz="0.01 0 0.095"/>
  </joint>
  <!-- BASE -->
  <link name="r_hand_base_link">
    <visual>
      <geometry>
        <mesh filename="package://tomm_description/meshes/hand/base_link.STL"/>
      </geometry>
      <origin rpy="0 0 0" xyz="0 0 0 "/>
       --&gt;

		
      <material name="black">
        <color rgba="0.2 0.2 0.2 1"/>
      </material>
    </visual>
    <collision>
      <origin rpy="0 0 0" xyz="-0.009300 0 -0.0475"/>
      <geometry>
        <box size="0.0408 0.1130 0.095"/>
      </geometry>
    </collision>
    <inertial>
      <origin rpy="0 0 0" xyz="0 0 0.0475"/>
      <mass value="0.4154"/>
      <inertia ixx="1e-4" ixy="0.0" ixz="0.0" iyy="1e-4" iyz="0.0" izz="1e-4"/>
    </inertial>
  </link>
  <!-- ============================================================================= -->
  <!-- FINGERS -->
  <!-- [LINK 0, 4, 8] -->
  <link name="r_hand_link_index_0">
    <visual>
      <geometry>
        <mesh filename="package://tomm_description/meshes/hand/link_0.0.STL"/>
      </geometry>
      <material name="black"/>
    </visual>
    <collision>
      <geometry>
        <box size="0.0196 0.0275 0.0164"/>
      </geometry>
      <origin rpy="0 0 0" xyz="0 0 0.0082"/>
    </collision>
    <inertial>
      <mass value="0.0119"/>
      <origin rpy="0 0 0" xyz="0 0 0"/>
      <inertia ixx="1.01666658333e-06" ixy="0.0" ixz="0.0" iyy="6.47677333333e-07" iyz="0.0" izz="1.01666658333e-06"/>
    </inertial>
  </link>
  <joint name="r_hand_joint_index_0" type="fixed">
    <axis xyz="0 0 1"/>
    <limit effort="0" lower="-0.47" upper="0.47" velocity="0"/>
    <parent link="r_hand_base_link"/>
    <child link="r_hand_link_index_0"/>
    <origin rpy="-0.08726646255 0 0" xyz="0 0.0435 -0.001542"/>
  </joint>
  <!-- [LINK 1, 5, 9] -->
  <link name="r_hand_link_index_1">
    <visual>
      <geometry>
        <mesh filename="package://tomm_description/meshes/hand/link_1.0.STL"/>
      </geometry>
      <material name="black"/>
    </visual>
    <collision>
      <geometry>
        <box size="0.0196 0.0275 0.054"/>
      </geometry>
      <origin rpy="0 0 0" xyz="0 0 0.027"/>
    </collision>
    <inertial>
      <mass value="0.065"/>
      <origin rpy="0 0 0" xyz="0 0 0"/>
      <inertia ixx="7.95654166667e-05" ixy="1.7199e-05" ixz="8.75875e-06" iyy="2.47088833333e-05" iyz="2.413125e-05" izz="7.95654166667e-05"/>
    </inertial>
  </link>
  <joint name="r_hand_joint_index_1" type="fixed">
    <limit effort="0" lower="-0.196" upper="1.61" velocity="0"/>
    <axis xyz="0 1 0"/>
    <parent link="r_hand_link_index_0"/>
    <child link="r_hand_link_index_1"/>
    <origin xyz="0 0 0.0164"/>
  </joint>
  <!-- [LINK 2, 6, 10]-->
  <link name="r_hand_link_index_2">
    <visual>
      <geometry>
        <mesh filename="package://tomm_description/meshes/hand/link_2.0.STL"/>
      </geometry>
      <material name="black"/>
    </visual>
    <collision>
      <geometry>
        <box size="0.0196 0.0275 0.0384"/>
      </geometry>
      <origin rpy="0 0 0" xyz="0 0 0.0192"/>
    </collision>
    <inertial>
      <mass value="0.0355"/>
      <origin rpy="0 0 0" xyz="0 0 0"/>
      <inertia ixx="2.63979183333e-05" ixy="6.67968e-06" ixz="4.783625e-06" iyy="1.34948516667e-05" iyz="9.372e-06" izz="2.63979183333e-05"/>
    </inertial>
  </link>
  <joint name="r_hand_joint_index_2" type="fixed">
    <axis xyz="0 1 0"/>
    <limit effort="0" lower="-0.174" upper="1.709" velocity="0"/>
    <parent link="r_hand_link_index_1"/>
    <child link="r_hand_link_index_2"/>
    <origin xyz="0 0 0.054"/>
  </joint>
  <!-- [LINK 3, 7, 11] -->
  <link name="r_hand_link_index_3">
    <visual>
      <geometry>
        <mesh filename="package://tomm_description/meshes/hand/link_3.0.STL"/>
      </geometry>
      <material name="black"/>
    </visual>
    <collision>
      <geometry>
        <box size="0.0196 0.0275 0.0267"/>
      </geometry>
      <origin rpy="0 0 0" xyz="0 0 0.01335"/>
    </collision>
    <inertial>
      <mass value="0.0096"/>
      <origin rpy="0 0 0" xyz="0 0 0"/>
      <inertia ixx="4.701248e-06" ixy="1.255968e-06" ixz="1.2936e-06" iyy="3.649312e-06" iyz="1.7622e-06" izz="4.701248e-06"/>
    </inertial>
  </link>
  <joint name="r_hand_joint_index_3" type="fixed">
    <axis xyz="0 1 0"/>
    <limit effort="0" lower="-0.227" upper="1.618" velocity="0"/>
    <parent link="r_hand_link_index_2"/>
    <child link="r_hand_link_index_3"/>
    <origin xyz="0 0 0.0384"/>
  </joint>
  <!-- [FINGER TIP] -->
  <link name="r_hand_link_index_3_tip">
    <visual>
      <geometry>
        <mesh filename="package://tomm_description/meshes/hand/link_3.0_tip.STL"/>
      </geometry>
      <material name="white">
        <color rgba=".9 .9 .9 1"/>
      </material>
    </visual>
    <collision>
      <geometry>
        <sphere radius="0.012"/>
      </geometry>
    </collision>
    <inertial>
      <mass value="0.0168"/>
      <origin rpy="0 0 0" xyz="0 0 0"/>
      <inertia ixx="9.68e-07" ixy="0" ixz="0" iyy="9.68e-07" iyz="0" izz="9.68e-07"/>
    </inertial>
  </link>
  <joint name="r_hand_joint_index_3_tip" type="fixed">
    <parent link="r_hand_link_index_3"/>
    <child link="r_hand_link_index_3_tip"/>
    <origin rpy="0 0 0" xyz="0 0 0.0267"/>
  </joint>
  <!-- <xacro:finger_transmission prefix="${prefix}" finger_label="${finger_label}"/>  -->
  <!-- <xacro:allegro_hand_gazebo prefix="${prefix}" finger_label="${finger_label}"/>  -->
  <!-- [LINK 0, 4, 8] -->
  <link name="r_hand_link_middle_0">
    <visual>
      <geometry>
        <mesh filename="package://tomm_description/meshes/hand/link_0.0.STL"/>
      </geometry>
      <material name="black"/>
    </visual>
    <collision>
      <geometry>
        <box size="0.0196 0.0275 0.0164"/>
      </geometry>
      <origin rpy="0 0 0" xyz="0 0 0.0082"/>
    </collision>
    <inertial>
      <mass value="0.0119"/>
      <origin rpy="0 0 0" xyz="0 0 0"/>
      <inertia ixx="1.01666658333e-06" ixy="0.0" ixz="0.0" iyy="6.47677333333e-07" iyz="0.0" izz="1.01666658333e-06"/>
    </inertial>
  </link>
  <joint name="r_hand_joint_middle_0" type="fixed">
    <axis xyz="0 0 1"/>
    <limit effort="0" lower="-0.47" upper="0.47" velocity="0"/>
    <parent link="r_hand_base_link"/>
    <child link="r_hand_link_middle_0"/>
    <origin rpy="0.0 0 0" xyz="0 0 0.0007"/>
  </joint>
  <!-- [LINK 1, 5, 9] -->
  <link name="r_hand_link_middle_1">
    <visual>
      <geometry>
        <mesh filename="package://tomm_description/meshes/hand/link_1.0.STL"/>
      </geometry>
      <material name="black"/>
    </visual>
    <collision>
      <geometry>
        <box size="0.0196 0.0275 0.054"/>
      </geometry>
      <origin rpy="0 0 0" xyz="0 0 0.027"/>
    </collision>
    <inertial>
      <mass value="0.065"/>
      <origin rpy="0 0 0" xyz="0 0 0"/>
      <inertia ixx="7.95654166667e-05" ixy="1.7199e-05" ixz="8.75875e-06" iyy="2.47088833333e-05" iyz="2.413125e-05" izz="7.95654166667e-05"/>
    </inertial>
  </link>
  <joint name="r_hand_joint_middle_1" type="fixed">
    <limit effort="0" lower="-0.196" upper="1.61" velocity="0"/>
    <axis xyz="0 1 0"/>
    <parent link="r_hand_link_middle_0"/>
    <child link="r_hand_link_middle_1"/>
    <origin xyz="0 0 0.0164"/>
  </joint>
  <!-- [LINK 2, 6, 10]-->
  <link name="r_hand_link_middle_2">
    <visual>
      <geometry>
        <mesh filename="package://tomm_description/meshes/hand/link_2.0.STL"/>
      </geometry>
      <material name="black"/>
    </visual>
    <collision>
      <geometry>
        <box size="0.0196 0.0275 0.0384"/>
      </geometry>
      <origin rpy="0 0 0" xyz="0 0 0.0192"/>
    </collision>
    <inertial>
      <mass value="0.0355"/>
      <origin rpy="0 0 0" xyz="0 0 0"/>
      <inertia ixx="2.63979183333e-05" ixy="6.67968e-06" ixz="4.783625e-06" iyy="1.34948516667e-05" iyz="9.372e-06" izz="2.63979183333e-05"/>
    </inertial>
  </link>
  <joint name="r_hand_joint_middle_2" type="fixed">
    <axis xyz="0 1 0"/>
    <limit effort="0" lower="-0.174" upper="1.709" velocity="0"/>
    <parent link="r_hand_link_middle_1"/>
    <child link="r_hand_link_middle_2"/>
    <origin xyz="0 0 0.054"/>
  </joint>
  <!-- [LINK 3, 7, 11] -->
  <link name="r_hand_link_middle_3">
    <visual>
      <geometry>
        <mesh filename="package://tomm_description/meshes/hand/link_3.0.STL"/>
      </geometry>
      <material name="black"/>
    </visual>
    <collision>
      <geometry>
        <box size="0.0196 0.0275 0.0267"/>
      </geometry>
      <origin rpy="0 0 0" xyz="0 0 0.01335"/>
    </collision>
    <inertial>
      <mass value="0.0096"/>
      <origin rpy="0 0 0" xyz="0 0 0"/>
      <inertia ixx="4.701248e-06" ixy="1.255968e-06" ixz="1.2936e-06" iyy="3.649312e-06" iyz="1.7622e-06" izz="4.701248e-06"/>
    </inertial>
  </link>
  <joint name="r_hand_joint_middle_3" type="fixed">
    <axis xyz="0 1 0"/>
    <limit effort="0" lower="-0.227" upper="1.618" velocity="0"/>
    <parent link="r_hand_link_middle_2"/>
    <child link="r_hand_link_middle_3"/>
    <origin xyz="0 0 0.0384"/>
  </joint>
  <!-- [FINGER TIP] -->
  <link name="r_hand_link_middle_3_tip">
    <visual>
      <geometry>
        <mesh filename="package://tomm_description/meshes/hand/link_3.0_tip.STL"/>
      </geometry>
      <material name="white">
        <color rgba=".9 .9 .9 1"/>
      </material>
    </visual>
    <collision>
      <geometry>
        <sphere radius="0.012"/>
      </geometry>
    </collision>
    <inertial>
      <mass value="0.0168"/>
      <origin rpy="0 0 0" xyz="0 0 0"/>
      <inertia ixx="9.68e-07" ixy="0" ixz="0" iyy="9.68e-07" iyz="0" izz="9.68e-07"/>
    </inertial>
  </link>
  <joint name="r_hand_joint_middle_3_tip" type="fixed">
    <parent link="r_hand_link_middle_3"/>
    <child link="r_hand_link_middle_3_tip"/>
    <origin rpy="0 0 0" xyz="0 0 0.0267"/>
  </joint>
  <!-- <xacro:finger_transmission prefix="${prefix}" finger_label="${finger_label}"/>  -->
  <!-- <xacro:allegro_hand_gazebo prefix="${prefix}" finger_label="${finger_label}"/>  -->
  <!-- [LINK 0, 4, 8] -->
  <link name="r_hand_link_ring_0">
    <visual>
      <geometry>
        <mesh filename="package://tomm_description/meshes/hand/link_0.0.STL"/>
      </geometry>
      <material name="black"/>
    </visual>
    <collision>
      <geometry>
        <box size="0.0196 0.0275 0.0164"/>
      </geometry>
      <origin rpy="0 0 0" xyz="0 0 0.0082"/>
    </collision>
    <inertial>
      <mass value="0.0119"/>
      <origin rpy="0 0 0" xyz="0 0 0"/>
      <inertia ixx="1.01666658333e-06" ixy="0.0" ixz="0.0" iyy="6.47677333333e-07" iyz="0.0" izz="1.01666658333e-06"/>
    </inertial>
  </link>
  <joint name="r_hand_joint_ring_0" type="fixed">
    <axis xyz="0 0 1"/>
    <limit effort="0" lower="-0.47" upper="0.47" velocity="0"/>
    <parent link="r_hand_base_link"/>
    <child link="r_hand_link_ring_0"/>
    <origin rpy="0.08726646255 0 0" xyz="0 -0.0435 -0.001542"/>
  </joint>
  <!-- [LINK 1, 5, 9] -->
  <link name="r_hand_link_ring_1">
    <visual>
      <geometry>
        <mesh filename="package://tomm_description/meshes/hand/link_1.0.STL"/>
      </geometry>
      <material name="black"/>
    </visual>
    <collision>
      <geometry>
        <box size="0.0196 0.0275 0.054"/>
      </geometry>
      <origin rpy="0 0 0" xyz="0 0 0.027"/>
    </collision>
    <inertial>
      <mass value="0.065"/>
      <origin rpy="0 0 0" xyz="0 0 0"/>
      <inertia ixx="7.95654166667e-05" ixy="1.7199e-05" ixz="8.75875e-06" iyy="2.47088833333e-05" iyz="2.413125e-05" izz="7.95654166667e-05"/>
    </inertial>
  </link>
  <joint name="r_hand_joint_ring_1" type="fixed">
    <limit effort="0" lower="-0.196" upper="1.61" velocity="0"/>
    <axis xyz="0 1 0"/>
    <parent link="r_hand_link_ring_0"/>
    <child link="r_hand_link_ring_1"/>
    <origin xyz="0 0 0.0164"/>
  </joint>
  <!-- [LINK 2, 6, 10]-->
  <link name="r_hand_link_ring_2">
    <visual>
      <geometry>
        <mesh filename="package://tomm_description/meshes/hand/link_2.0.STL"/>
      </geometry>
      <material name="black"/>
    </visual>
    <collision>
      <geometry>
        <box size="0.0196 0.0275 0.0384"/>
      </geometry>
      <origin rpy="0 0 0" xyz="0 0 0.0192"/>
    </collision>
    <inertial>
      <mass value="0.0355"/>
      <origin rpy="0 0 0" xyz="0 0 0"/>
      <inertia ixx="2.63979183333e-05" ixy="6.67968e-06" ixz="4.783625e-06" iyy="1.34948516667e-05" iyz="9.372e-06" izz="2.63979183333e-05"/>
    </inertial>
  </link>
  <joint name="r_hand_joint_ring_2" type="fixed">
    <axis xyz="0 1 0"/>
    <limit effort="0" lower="-0.174" upper="1.709" velocity="0"/>
    <parent link="r_hand_link_ring_1"/>
    <child link="r_hand_link_ring_2"/>
    <origin xyz="0 0 0.054"/>
  </joint>
  <!-- [LINK 3, 7, 11] -->
  <link name="r_hand_link_ring_3">
    <visual>
      <geometry>
        <mesh filename="package://tomm_description/meshes/hand/link_3.0.STL"/>
      </geometry>
      <material name="black"/>
    </visual>
    <collision>
      <geometry>
        <box size="0.0196 0.0275 0.0267"/>
      </geometry>
      <origin rpy="0 0 0" xyz="0 0 0.01335"/>
    </collision>
    <inertial>
      <mass value="0.0096"/>
      <origin rpy="0 0 0" xyz="0 0 0"/>
      <inertia ixx="4.701248e-06" ixy="1.255968e-06" ixz="1.2936e-06" iyy="3.649312e-06" iyz="1.7622e-06" izz="4.701248e-06"/>
    </inertial>
  </link>
  <joint name="r_hand_joint_ring_3" type="fixed">
    <axis xyz="0 1 0"/>
    <limit effort="0" lower="-0.227" upper="1.618" velocity="0"/>
    <parent link="r_hand_link_ring_2"/>
    <child link="r_hand_link_ring_3"/>
    <origin xyz="0 0 0.0384"/>
  </joint>
  <!-- [FINGER TIP] -->
  <link name="r_hand_link_ring_3_tip">
    <visual>
      <geometry>
        <mesh filename="package://tomm_description/meshes/hand/link_3.0_tip.STL"/>
      </geometry>
      <material name="white">
        <color rgba=".9 .9 .9 1"/>
      </material>
    </visual>
    <collision>
      <geometry>
        <sphere radius="0.012"/>
      </geometry>
    </collision>
    <inertial>
      <mass value="0.0168"/>
      <origin rpy="0 0 0" xyz="0 0 0"/>
      <inertia ixx="9.68e-07" ixy="0" ixz="0" iyy="9.68e-07" iyz="0" izz="9.68e-07"/>
    </inertial>
  </link>
  <joint name="r_hand_joint_ring_3_tip" type="fixed">
    <parent link="r_hand_link_ring_3"/>
    <child link="r_hand_link_ring_3_tip"/>
    <origin rpy="0 0 0" xyz="0 0 0.0267"/>
  </joint>
  <!-- <xacro:finger_transmission prefix="${prefix}" finger_label="${finger_label}"/>  -->
  <!-- <xacro:allegro_hand_gazebo prefix="${prefix}" finger_label="${finger_label}"/>  -->
  <!-- THUMB -->
  <!-- [LINK 12] -->
  <link name="r_hand_link_thumb_0">
    <visual>
      <geometry>
        <!-- RIGHT -->
        <mesh filename="package://tomm_description/meshes/hand/link_12.0_right.STL"/>
        <!-- LEFT -->
        <!-- <mesh filename="package://tomm_description/meshes/hand/link_12.0_left.STL" /> -->
      </geometry>
      <material name="black">
        <color rgba=".2 .2 .2 1"/>
      </material>
    </visual>
    <collision>
      <geometry>
        <box size="0.0358 0.034 0.0455"/>
      </geometry>
      <!-- RIGHT -->
      <origin rpy="0 0 0" xyz="-0.0179 0.009 0.0145"/>
      <!-- LEFT -->
      <!-- <origin rpy="0 0 0" xyz="${-0.0358/2+0.0} ${-.018/2} ${.029/2}"/> -->
    </collision>
    <inertial>
      <mass value="0.0176"/>
      <origin rpy="0 0 0" xyz="0 0 0"/>
      <inertia ixx="1.89273333333e-5" ixy="7.16716e-06" ixz="5.35568e-06" iyy="1.43008213333e-05" iyz="6.8068e-06" izz="1.89273333333e-05"/>
    </inertial>
  </link>
  <joint name="r_hand_joint_thumb_0" type="fixed">
    <axis xyz="-1 0 0"/>
    <limit effort="0" lower="0.263" upper="1.396" velocity="0"/>
    <parent link="r_hand_base_link"/>
    <child link="r_hand_link_thumb_0"/>
    <origin rpy="0 -1.65806278845 -1.5707963259" xyz="-0.0182 0.019333 -0.045987"/>
    <dynamics damping="1" friction="0"/>
  </joint>
  <!-- [LINK 13] -->
  <link name="r_hand_link_thumb_1">
    <visual>
      <geometry>
        <mesh filename="package://tomm_description/meshes/hand/link_13.0.STL"/>
      </geometry>
      <material name="black">
        <color rgba=".2 .2 .2 1"/>
      </material>
    </visual>
    <collision>
      <geometry>
        <box size="0.0196 0.0275 0.0177"/>
      </geometry>
      <origin rpy="0 0 0" xyz="0 0 0.00885"/>
    </collision>
    <inertial>
      <mass value="0.0119"/>
      <origin rpy="0 0 0" xyz="0 0 0"/>
      <inertia ixx="4.24250866667e-06" ixy="1.032087e-06" ixz="1.603525e-06" iyy="4.52362633333e-06" iyz="1.44808125e-06" izz="4.24250866667e-06"/>
    </inertial>
  </link>
  <joint name="r_hand_joint_thumb_1" type="fixed">
    <axis xyz="0 0 1"/>
    <limit effort="0" lower="-0.105" upper="1.163" velocity="0"/>
    <parent link="r_hand_link_thumb_0"/>
    <child link="r_hand_link_thumb_1"/>
    <!-- RIGHT -->
    <origin xyz="-0.027 0.005 0.0399"/>
    <!-- LEFT -->
    <!-- <origin xyz="-0.027 -0.005 0.0399"/> -->
    <dynamics damping="1" friction="0"/>
  </joint>
  <!-- [LINK 14] -->
  <link name="r_hand_link_thumb_2">
    <visual>
      <geometry>
        <mesh filename="package://tomm_description/meshes/hand/link_14.0.STL"/>
      </geometry>
      <material name="black">
		  	</material>
    </visual>
    <collision>
      <geometry>
        <box size="0.0196 0.0275 0.0514"/>
      </geometry>
      <origin rpy="0 0 0" xyz="0 0 0.0257"/>
    </collision>
    <inertial>
      <mass value="0.038"/>
      <origin rpy="0 0 0" xyz="0 0 0"/>
      <inertia ixx="4.30439933333e-05" ixy="9.57068e-06" ixz="5.1205e-06" iyy="1.44451933333e-05" iyz="1.342825e-05" izz="4.30439933333e-05"/>
    </inertial>
  </link>
  <joint name="r_hand_joint_thumb_2" type="fixed">
    <axis xyz="0 1 0"/>
    <limit effort="0" lower="-0.189" upper="1.644" velocity="0"/>
    <parent link="r_hand_link_thumb_1"/>
    <child link="r_hand_link_thumb_2"/>
    <origin xyz="0 0 0.0177"/>
    <dynamics damping="1" friction="0"/>
  </joint>
  <!-- [LINK 15] -->
  <link name="r_hand_link_thumb_3">
    <visual>
      <geometry>
        <mesh filename="package://tomm_description/meshes/hand/link_15.0.STL"/>
      </geometry>
      <material name="black">
    	</material>
    </visual>
    <collision>
      <geometry>
        <box size="0.0196 0.0275 0.0423"/>
      </geometry>
      <origin rpy="0 0 0" xyz="0 0 0.02115"/>
    </collision>
    <inertial>
      <mass value="0.0388"/>
      <origin rpy="0 0 0" xyz="0 0 0"/>
      <inertia ixx="3.29223173333e-05" ixy="8.042076e-06" ixz="5.2283e-06" iyy="1.47493026667e-5" iyz="1.1283525e-5" izz="3.29223173333e-05"/>
    </inertial>
  </link>
  <joint name="r_hand_joint_thumb_3" type="fixed">
    <axis xyz="0 1 0"/>
    <limit effort="0" lower="-0.162" upper="1.719" velocity="0"/>
    <parent link="r_hand_link_thumb_2"/>
    <child link="r_hand_link_thumb_3"/>
    <origin xyz="0 0 0.0514"/>
    <dynamics damping="1" friction="0"/>
  </joint>
  <!-- [FINGER TIP] -->
  <link name="r_hand_link_thumb_3_tip">
    <visual>
      <geometry>
        <mesh filename="package://tomm_description/meshes/hand/link_15.0_tip.STL"/>
      </geometry>
      <material name="white">
        <color rgba=".9 .9 .9 1"/>
      </material>
    </visual>
    <collision>
      <geometry>
        <sphere radius="0.012"/>
      </geometry>
      <origin rpy="0 0 0" xyz="0 0 0"/>
    </collision>
    <inertial>
      <mass value="0.0168"/>
      <origin rpy="0 0 0" xyz="0 0 0"/>
      <inertia ixx="9.68e-07" ixy="0" ixz="0" iyy="9.68e-07" iyz="0" izz="9.68e-07"/>
    </inertial>
  </link>
  <joint name="r_hand_joint_thumb_3_tip" type="fixed">
    <parent link="r_hand_link_thumb_3"/>
    <child link="r_hand_link_thumb_3_tip"/>
    <origin rpy="0 0 0" xyz="0 0 0.0423"/>
    <!--0.0267000000000005-->
  </joint>
  <!-- <xacro:finger_transmission prefix="${prefix}" finger_label="${finger_label}"/>  -->
  <!-- <xacro:allegro_hand_gazebo prefix="${prefix}" finger_label="${finger_label}"/>  -->
  <joint name="r_hand_base_joint" type="fixed">
    <parent link="r_hand_base_adapter_link"/>
    <child link="r_hand_base_link"/>
    <origin rpy="0 0 0" xyz="0.01 0 0.095"/>
  </joint>
  <!-- Sensors -->
  <link name="front_laser_scanner_link">
    <visual>
      <origin rpy="0 0 0" xyz="0 0 0"/>
      <geometry>
        <cylinder length="0.05" radius="0.02"/>
      </geometry>
      <material name="light_grey">
        <color rgba="0.5 0.5 0.5 1"/>
      </material>
    </visual>
    <collision>
      <origin rpy="0 0 0" xyz="0 0 0"/>
      <geometry>
        <cylinder length="0.05" radius="0.02"/>
      </geometry>
    </collision>
  </link>
  <joint name="front_laser_scanner" type="fixed">
    <parent link="base_link"/>
    <child link="front_laser_scanner_link"/>
    <origin rpy="3.14 0 0.785" xyz="0.41464 0.26511 0.28"/>
  </joint>
  <link name="rear_laser_scanner_link">
    <visual>
      <origin rpy="0 0 0" xyz="0 0 0"/>
      <geometry>
        <cylinder length="0.05" radius="0.02"/>
      </geometry>
      <material name="light_grey"/>
    </visual>
    <collision>
      <origin rpy="0 0 0" xyz="0 0 0"/>
      <geometry>
        <cylinder length="0.05" radius="0.02"/>
      </geometry>
    </collision>
  </link>
  <joint name="rear_laser_scanner" type="fixed">
    <parent link="base_link"/>
    <child link="rear_laser_scanner_link"/>
    <origin rpy="3.14 0 -2.355" xyz="-0.46614 -0.26415 0.28"/>
  </joint>
  <gazebo reference="r_wrist_3_joint">
    <provideFeedback>true</provideFeedback>
  </gazebo>
  <gazebo>
    <plugin filename="libgazebo_ros_ft_sensor.so" name="ft_sensor">
      <update_rate>200</update_rate>
      <topicName>right_wrist_ft</topicName>
      <jointName>r_wrist_3_joint</jointName>
      <noise>
        <type>gaussian</type>
        <mean>0.0</mean>
        <stddev>0.003</stddev>
      </noise>
    </plugin>
  </gazebo>
  <gazebo reference="l_wrist_3_joint">
    <provideFeedback>true</provideFeedback>
  </gazebo>
  <gazebo>
    <plugin filename="libgazebo_ros_ft_sensor.so" name="ft_sensor">
      <update_rate>200</update_rate>
      <topicName>left_wrist_ft</topicName>
      <jointName>l_wrist_3_joint</jointName>
      <noise>
        <type>gaussian</type>
        <mean>0.0</mean>
        <stddev>0.003</stddev>
      </noise>
    </plugin>
  </gazebo>
  <gazebo reference="front_laser_scanner_link">
    <sensor name="front_lidar_sensor" type="ray">
      <pose>0 0 0 0 0 0</pose>
      <visualize>false</visualize>
      <update_rate>50</update_rate>
      <ray>
        <scan>
          <horizontal>
            <samples>180</samples>
            <resolution>1</resolution>
            <min_angle>0.0</min_angle>
            <max_angle>3.141</max_angle>
          </horizontal>
        </scan>
        <range>
          <min>0.02</min>
          <max>5.6</max>
          <resolution>0.01</resolution>
        </range>
      </ray>
      <plugin filename="libgazebo_ros_laser.so" name="gazebo_ros_laser">
        <frameName>/front_laser_scanner_link</frameName>
        <topicName>front_scan</topicName>
        <gaussianNoise>0.03</gaussianNoise>
        <hokuyoMinIntensity>101</hokuyoMinIntensity>
        <updateRate>50</updateRate>
        <alwaysOn>true</alwaysOn>
      </plugin>
    </sensor>
  </gazebo>
  <gazebo reference="rear_laser_scanner_link">
    <sensor name="rear_lidar_sensor" type="ray">
      <pose>0 0 0 0 0 0</pose>
      <visualize>false</visualize>
      <update_rate>50</update_rate>
      <ray>
        <scan>
          <horizontal>
            <samples>180</samples>
            <resolution>1</resolution>
            <min_angle>0.0</min_angle>
            <max_angle>3.141</max_angle>
          </horizontal>
        </scan>
        <range>
          <min>0.02</min>
          <max>5.6</max>
          <resolution>0.01</resolution>
        </range>
      </ray>
      <plugin filename="libgazebo_ros_laser.so" name="gazebo_ros_laser">
        <frameName>/rear_laser_scanner_link</frameName>
        <topicName>rear_scan</topicName>
        <gaussianNoise>0.03</gaussianNoise>
        <hokuyoMinIntensity>101</hokuyoMinIntensity>
        <updateRate>50</updateRate>
        <alwaysOn>true</alwaysOn>
      </plugin>
    </sensor>
  </gazebo>
  <gazebo reference="torso_link">
    <sensor name="p101e_patch" type="skin">
      <always_on>true</always_on>
      <pose>0 0 0 0 0 0</pose>
      <visualize>false</visualize>
      <update_rate>100.0</update_rate>
      <ray>
        <scan>
          <horizontal>
            <samples>0</samples>
            <resolution>1</resolution>
            <min_angle>0</min_angle>
            <max_angle>0</max_angle>
          </horizontal>
        </scan>
        <range>
          <min>0.0</min>
          <max>0.1</max>
          <resolution>0.01</resolution>
        </range>
      </ray>
      <plugin filename="libgazebo_skin_plugin.so" name="gazebo_skin_plugin">
        <frameName>/torso_link</frameName>
        <topicName>p101e</topicName>
        <gaussianNoise>0.0</gaussianNoise>
        <updateRate>100.0</updateRate>
        <alwaysOn>true</alwaysOn>
      </plugin>
    </sensor>
  </gazebo>
  <gazebo reference="r_upper_arm_link">
    <sensor name="p102e_patch" type="skin">
      <always_on>true</always_on>
      <pose>0 0 0 0 0 0</pose>
      <visualize>false</visualize>
      <update_rate>100.0</update_rate>
      <ray>
        <scan>
          <horizontal>
            <samples>0</samples>
            <resolution>1</resolution>
            <min_angle>0</min_angle>
            <max_angle>0</max_angle>
          </horizontal>
        </scan>
        <range>
          <min>0.0</min>
          <max>0.1</max>
          <resolution>0.01</resolution>
        </range>
      </ray>
      <plugin filename="libgazebo_skin_plugin.so" name="gazebo_skin_plugin">
        <frameName>/r_upper_arm_link</frameName>
        <topicName>p102e</topicName>
        <gaussianNoise>0.0</gaussianNoise>
        <updateRate>100.0</updateRate>
        <alwaysOn>true</alwaysOn>
      </plugin>
    </sensor>
  </gazebo>
  <gazebo reference="r_forearm_link">
    <sensor name="p103e_patch" type="skin">
      <always_on>true</always_on>
      <pose>0 0 0 0 0 0</pose>
      <visualize>false</visualize>
      <update_rate>100.0</update_rate>
      <ray>
        <scan>
          <horizontal>
            <samples>0</samples>
            <resolution>1</resolution>
            <min_angle>0</min_angle>
            <max_angle>0</max_angle>
          </horizontal>
        </scan>
        <range>
          <min>0.0</min>
          <max>0.1</max>
          <resolution>0.01</resolution>
        </range>
      </ray>
      <plugin filename="libgazebo_skin_plugin.so" name="gazebo_skin_plugin">
        <frameName>/r_forearm_link</frameName>
        <topicName>p103e</topicName>
        <gaussianNoise>0.0</gaussianNoise>
        <updateRate>100.0</updateRate>
        <alwaysOn>true</alwaysOn>
      </plugin>
    </sensor>
  </gazebo>
  <gazebo reference="l_upper_arm_link">
    <sensor name="p201e_patch" type="skin">
      <always_on>true</always_on>
      <pose>0 0 0 0 0 0</pose>
      <visualize>false</visualize>
      <update_rate>100.0</update_rate>
      <ray>
        <scan>
          <horizontal>
            <samples>0</samples>
            <resolution>1</resolution>
            <min_angle>0</min_angle>
            <max_angle>0</max_angle>
          </horizontal>
        </scan>
        <range>
          <min>0.0</min>
          <max>0.1</max>
          <resolution>0.01</resolution>
        </range>
      </ray>
      <plugin filename="libgazebo_skin_plugin.so" name="gazebo_skin_plugin">
        <frameName>/l_upper_arm_link</frameName>
        <topicName>p201e</topicName>
        <gaussianNoise>0.0</gaussianNoise>
        <updateRate>100.0</updateRate>
        <alwaysOn>true</alwaysOn>
      </plugin>
    </sensor>
  </gazebo>
  <gazebo reference="l_forearm_link">
    <sensor name="p202e_patch" type="skin">
      <always_on>true</always_on>
      <pose>0 0 0 0 0 0</pose>
      <visualize>false</visualize>
      <update_rate>100.0</update_rate>
      <ray>
        <scan>
          <horizontal>
            <samples>0</samples>
            <resolution>1</resolution>
            <min_angle>0</min_angle>
            <max_angle>0</max_angle>
          </horizontal>
        </scan>
        <range>
          <min>0.0</min>
          <max>0.1</max>
          <resolution>0.01</resolution>
        </range>
      </ray>
      <plugin filename="libgazebo_skin_plugin.so" name="gazebo_skin_plugin">
        <frameName>/l_forearm_link</frameName>
        <topicName>p202e</topicName>
        <gaussianNoise>0.0</gaussianNoise>
        <updateRate>100.0</updateRate>
        <alwaysOn>true</alwaysOn>
      </plugin>
    </sensor>
  </gazebo>
  <gazebo reference="r_hand_base_link">
    <sensor name="p301e_patch" type="skin">
      <always_on>true</always_on>
      <pose>0 0 0 0 0 0</pose>
      <visualize>false</visualize>
      <update_rate>100.0</update_rate>
      <ray>
        <scan>
          <horizontal>
            <samples>0</samples>
            <resolution>1</resolution>
            <min_angle>0</min_angle>
            <max_angle>0</max_angle>
          </horizontal>
        </scan>
        <range>
          <min>0.0</min>
          <max>0.1</max>
          <resolution>0.01</resolution>
        </range>
      </ray>
      <plugin filename="libgazebo_skin_plugin.so" name="gazebo_skin_plugin">
        <frameName>/r_hand_base_link</frameName>
        <topicName>p301e</topicName>
        <gaussianNoise>0.0</gaussianNoise>
        <updateRate>100.0</updateRate>
        <alwaysOn>true</alwaysOn>
      </plugin>
    </sensor>
  </gazebo>
  <gazebo reference="l_hand_base_link">
    <sensor name="p401e_patch" type="skin">
      <always_on>true</always_on>
      <pose>0 0 0 0 0 0</pose>
      <visualize>false</visualize>
      <update_rate>100.0</update_rate>
      <ray>
        <scan>
          <horizontal>
            <samples>0</samples>
            <resolution>1</resolution>
            <min_angle>0</min_angle>
            <max_angle>0</max_angle>
          </horizontal>
        </scan>
        <range>
          <min>0.0</min>
          <max>0.1</max>
          <resolution>0.01</resolution>
        </range>
      </ray>
      <plugin filename="libgazebo_skin_plugin.so" name="gazebo_skin_plugin">
        <frameName>/l_hand_base_link</frameName>
        <topicName>p401e</topicName>
        <gaussianNoise>0.0</gaussianNoise>
        <updateRate>100.0</updateRate>
        <alwaysOn>true</alwaysOn>
      </plugin>
    </sensor>
  </gazebo>
</robot>

